Workbook

Sheet Guide
B1: FINANCIAL ACCOUNTING HOMEWORK TEMPLATE
B3: Company name | C3: Laboratorios Dermolab | D3: ← fill in once, every sheet picks it up
B4: Period (e.g. Year 1) | C4: 2018–2021
B5: Currency / units | C5: €
B7: WORKFLOW (do the sheets in this order)
B8: 1. Journal: write every transaction as a journal entry (Dr = Cr). Give each entry a number (1, 2, 3a, 3b, …, CE).
B9: 2. T-Accounts: post each entry to its T-accounts, writing the entry # in the grey # columns. Beginning balances go on the BB row.
B10: 3. Balance Sheet: fills itself from the T-accounts (beginning and ending balances). Check that Assets = L + OE.
B11: 4. Income Statement: type the revenues/expenses from the P&L T-account. Expenses and losses go in as NEGATIVE numbers.
B12: 5. Cash Flow: type each cash movement from the Cash T-account in the direct method. The indirect method fills itself.
B13: 6. CF Worksheet (optional): the course's ΔCash = −ΔA* + ΔL + ΔOE table. Use it to check the indirect method line by line.
B14: 7. Every check cell must say OK in green. A red ERROR tells you how far off you are.
B16: COLOUR LEGEND
B17: 1,000 | C17: Blue text = number you type in (input)
B18: 1,000 | C18: Black text = formula (don't type over it)
B19: Assets | C19: Asset section header (your red)
B20: Account | C20: Asset T-account title
B21: L & OE | C21: Liabilities & owners' equity section header (your blue)
B22: Account | C22: Liability T-account title
B23: Account | C23: Owners' equity T-account title
B24: P&L | C24: Profit & loss for the period (temporary OE account)
B25: I/S | C25: Income statement (green family)
B26: C/F | C26: Cash flow statement (purple, with orange for CFI and cyan for CFF)
B27: OK | C27: Check passed
B28: ERROR | C28: Check failed. The number is the difference.
B30: DEBIT / CREDIT RULES (CN-230-E, T-accounts section)
B31: Account type | C31: Increase | D31: Decrease | E31: Normal balance | F31: Examples
B32: Assets | C32: Debit (left) | D32: Credit (right) | E32: Debit | F32: Cash, A/R, inventory, PPE
B33: Contra-assets | C33: Credit | D33: Debit | E33: Credit | F33: Accumulated depreciation / amortization
B34: Liabilities | C34: Credit | D34: Debit | E34: Credit | F34: A/P, taxes payable, loans
B35: Owners' equity | C35: Credit | D35: Debit | E35: Credit | F35: Share capital, retained profits
B36: P&L: revenues & gains | C36: Credit | E36: Credit | F36: Sales, financial income
B37: P&L: expenses & losses | C37: Debit | E37: Debit | F37: COGS, salaries, depreciation, tax
B38: Every entry: total debits = total credits. A = L + OE always holds. Debit/credit mean LEFT/RIGHT, not +/−.
B39: Closing entry (CE): Dr Profit for the period / Cr Retained profits (net profit). After it the P&L account is zero.
B40: Dividends are NOT an expense: Dr Retained profits / Cr Cash (or Dividends payable).
B42: EXAMPLE JOURNAL ENTRY (from the course note: a €10,000 loan received in cash)
B43: # / Account | C43: Dr | D43: Cr | E43: Effect | F43: Cash flow class
B44: 1 Cash | C44: 10000 | E44: A+ | F44: F (new loan)
B45: 1 Long-term bank loan | D45: 10000 | E45: L+
...

Sheet Case solution
B1: DERMOLAB – NON-CURRENT ASSETS: TREATMENT OF THE 11 EVENTS
B3: # | C3: Event | D3: Treatment | E3: Why (IFRS) | F3: Amount
B4: 1 | C4: Land donated by Viladecans (promised Jul 2018, formalized Jan 2019) | D4: Jan 2019: asset LAND at fair value; credit Grant/Donation as a LIABILITY. No entry in 2018. Land is not depreciated, so the grant is not released to the P&L (slide 2). | E4: A conditional promise isn't an asset until the condition (jobs) is met (IAS 20.7). A non-monetary grant is measured at FAIR VALUE (750,000, the expert appraisal); the 550,000 is only a tax value. | F4: 750000
B5: 2 | C5: Old premises sold (Oct 2018) | D5: Remove cost of land (5M) and of building (6M) and its accumulated depreciation (5.4M). Gain to P&L. | E5: Gain = price − book value. Land 10M − 5M = 5M; building 3M − 0.6M = 2.4M. Total gain 7.4M (non-recurring). Cash +13M is INVESTING. | F5: 7400000
B6: 3 | C6: Demolition 25,000 + levelling & drainage 100,000 | D6: CAPITALIZE as part of the LAND. | E6: Costs needed to get the land ready for its intended use are part of its cost (IAS 16.16b). Land is not depreciated, so neither are these costs. | F6: 125000
B7: 4 | C7: New building & production facilities (2019, in use Jan 2020) | D7: During 2019: construction in progress (not depreciated). Jan 2020: transfer to Buildings 620,000 and Facilities 310,000. | E7: All costs to bring the asset into use are capitalized: building 450,000 + management & permits 150,000; facilities 240,000 + installation 60,000. 2019 loan interest (30,000) is CAPITALIZED (IAS 23) and split by cost: 20,000 building (600/900) + 10,000 facilities (300/900). From 2020 interest is an expense (570,000 × 5% = 28,500). Depreciation: building 620,000 / 20 = 31,000/yr; facilities 310,000 / 10 = 31,000/yr. | F7: 930000
B8: 5 | C8: Moving equipment to the new plant (2020) | D8: EXPENSE everything: 7,000 + 1,000 insurance = 8,000 paid. Staff 450 h: no extra entry. | E8: Relocation costs are explicitly NOT part of an asset's cost (IAS 16.20-21). The 450 h × 20 = 9,000 of staff cost is already in salaries expense; recording it again would double count. The 45/h price is never used (it includes overhead and profit). | F8: 8000
B9: 6 | C9: Special maintenance +15% productivity | D9: CAPITALIZE as an improvement to machinery; depreciate over 10 years (4,000/yr from 2021). | E9: It increases future economic benefits (more output), so it is not ordinary repair & maintenance, which would be an expense (IAS 16.7, 16.12). | F9: 40000
B10: 7 | C10: New equipment bought in 2020 | D10: Cost = 200,000 − 2% (4,000) + 600 transport + own installation 100 h × (20 + 10) = 199,600. | E10: Purchase price NET of discounts plus every cost to bring it to working condition (IAS 16.16-17). Own staff at PRODUCTION COST: direct 20/h + reasonable overhead 10/h, never the 15/h profit. Credit P&L 'own work capitalized' because the salaries are already expensed. | F10: 199600
B11: 8 | C11: Patent bought (Jan 2021) + development (10,000 h × 42) | D11: Patent 1,000,000 and development 420,000 → INTANGIBLE ASSETS (1,420,000). Amortize over 10 years: 142,000 for 2021. | E11: Acquired patent = intangible at cost (IAS 38.25). Development is capitalized when technically feasible, approved and marketable (IAS 38.57). Use the ECONOMIC life (10) when it is shorter than the legal life (15). The slides charge a full year: 1,420,000 / 10 = 142,000. | F11: 1420000
B12: 9 | C12: Research on two new projects (Jul–Dec 2021) | D12: EXPENSE: external 224,000. The 17,000 h (≈714,000 at 42/h) are already in salaries expense. | E12: Research costs are ALWAYS expensed (IAS 38.54). 'Too early to determine the degree of development' = still research. | F12: 224000
B13: 10 | C13: Brand value rose to 3,000,000 | D13: NO ENTRY. | E13: Internally generated brands are never recognized as assets (IAS 38.63), and increases in value are not recorded. | F13: 0
B14: 11 | C14: Competitor launches a substitute (Dec 2021) | D14: IMPAIRMENT LOSS 278,000 to P&L. From 2022, amortize the new 1,000,000 over 5 years (200,000/yr). | E14: Book value 1,420,000 − 142,000 = 1,278,000. Recoverable amount = HIGHER of value in use (1,000,000) and fair value less costs to sell (800,000 offer) = 1,000,000 (IAS 36.18). Loss = 278,000. The 1,800,000 old estimate is irrelevant: an intangible is never written UP above cost. | F14: 278000
B16: P&L IMPACT BY YEAR (from these events only)
C17: Item | D17: 2018 / 2019 | E17: 2020 | F17: 2021
C18: Gain on sale of old premises (2) | D18: 7400000 | E18: 0 | F18: 0
C19: Relocation expenses (5) | D19: 0 | E19: -8000 | F19: 0
C20: Own work capitalized (7b, 8b) | D20: 0 | E20: 3000 | F20: 420000
C21: Research expense – external (9) | D21: 0 | E21: 0 | F21: -224000
C22: Interest expense (4) – 2019 capitalized | D22: 0 | E22: -28500 | F22: -27000
C23: Depreciation building & facilities (4, 6) | D23: 0 | E23: -62000 | F23: -66000
C24: Amortization patent & development (8) | D24: 0 | E24: 0 | F24: -142000
C25: Impairment loss Baldnessox (11) | D25: 0 | E25: 0 | F25: -278000
C26: Total effect on profit | D26: =SUM(D18:D25) -> 7400000 | E26: =SUM(E18:E25) -> -95500 | F26: =SUM(F18:F25) -> -317000
B27: 2018 / 2019 column: everything is 2018 (the gain). 2019 has no P&L effect: the interest is capitalized and the grant is deferred. Salaries of researchers/installers are not shown; they were already recorded as personnel expense.
B29: WHY IS THE P&L CREDITED IN EVENTS 7 AND 8? (and why it is DEBITED in 11)
B30: • The rule hasn't changed: an expense is a DEBIT to the P&L. In events 7 and 8 the expense was ALREADY debited, when the staff were paid during the year: Dr P&L – Salaries / Cr Cash.
B31: • Some of those salaries were not a cost of running the business: they created an asset (the installed equipment in 7, the Baldnessox development in 8). That part must leave the P&L and go into the asset.
B32: • To take a debit out of the P&L you CREDIT it: Dr Development costs (asset) 420,000 / Cr P&L 420,000. The net result: salaries 420,000 debit − 420,000 credit = 0 in the P&L, and the asset holds 420,000.
B33: • Spanish GAAP (by nature) shows the credit as an income line, 'Work carried out by the company for its own assets'. IFRS (by function) shows it as a reduction of salaries ('Salaries & other expenses − 3,000'). Same entry, two presentations (slide 11).
B34: • The asset is then expensed LATER, through amortization (event 11: 142,000 a year), so the cost reaches the P&L in the years when the product earns revenue.
B35: • Event 11 is the opposite: amortization 142,000 and impairment 278,000 are real losses of value, so the P&L is DEBITED. The CREDITS go to Accumulated amortization and Accumulated impairment, which are contra-assets that reduce the patent's book value to 1,000,000 (slide 36).
B37: ASSUMPTIONS (where the case is silent; the slides settle the rest)
B38: • Loan (4): 30,000 of principal (600,000 / 20) plus interest paid each December, starting Dec 2019. Slide 8 says 'Loan: 1 Jan 2020', but the case says January 2019, and the capitalized 2019 interest only works with 2019.
B39: • Facilities (4) come into use with the building in January 2020. The improvement (6) is depreciated over 10 years from 2021 (4,000/yr, slide 10).
B40: • New equipment (7): no useful life is given, so no depreciation is computed.
B41: • Old premises (2): their cost and accumulated depreciation are entered as beginning balances (BB), because only the sale is recorded here. The cash T-account starts at zero, so its ending balance is not the real bank balance.

Sheet Journal
B1: JOURNAL ENTRIES
B2: Company: | C2: =Guide!$C$3 -> Laboratorios Dermolab | E2: Period: | F2: =Guide!$C$4 -> 2018–2021
C4: TOTAL | E4: =SUM(E7:E106) -> 24320100 | F4: =SUM(F7:F106) -> 24320100 | G4: =IF(ABS(E4-F4)<0.5,"OK","ERROR: "&TEXT(E4-F4,"#,##0")) -> OK
B6: # | C6: Description of transaction | D6: Account (pick from list or type) | E6: Dr | F6: Cr | G6: Effect | H6: Cash flow | I6: Entry check | K6: Notes & reminders
B7: 1 | C7: Jul 2018 – land donation only PROMISED (condition: create local jobs) → no entry yet | D7: (no entry in 2018) | I7: =IF(B7="","",IF(ABS(SUMIF($B$7:$B$106,B7,$E$7:$E$106)-SUMIF($B$7:$B$106,B7,$F$7:$F$106))<0.5,"OK","ERROR: Dr≠Cr")) -> OK | K7: How to use
B8: 2 | C8: Oct 2018 – old premises sold: land 10,000,000 + building & facilities 3,000,000 | D8: Cash & cash equivalents | E8: 13000000 | G8: A+ | H8: I | I8: =IF(B8="","",IF(ABS(SUMIF($B$7:$B$106,B8,$E$7:$E$106)-SUMIF($B$7:$B$106,B8,$F$7:$F$106))<0.5,"OK","ERROR: Dr≠Cr")) -> OK | K8: One line per account touched. All lines of the same transaction share the same # (e.g. 3a, 3a).
B9: 2 | D9: Accum. depreciation – Buildings | E9: 5400000 | G9: Contra-A− | I9: =IF(B9="","",IF(ABS(SUMIF($B$7:$B$106,B9,$E$7:$E$106)-SUMIF($B$7:$B$106,B9,$F$7:$F$106))<0.5,"OK","ERROR: Dr≠Cr")) -> OK | K9: Write the debit lines first, then the credit lines (Dr Cash / Cr Loan).
B10: 2 | D10: Land | F10: 5000000 | G10: A− | I10: =IF(B10="","",IF(ABS(SUMIF($B$7:$B$106,B10,$E$7:$E$106)-SUMIF($B$7:$B$106,B10,$F$7:$F$106))<0.5,"OK","ERROR: Dr≠Cr")) -> OK | K10: For P&L lines, write e.g. 'P&L – Sales revenue' or 'P&L – Salaries expense' so the Income Statement is easy to build.
B11: 2 | D11: Buildings (old premises + new building) | F11: 6000000 | G11: A− | I11: =IF(B11="","",IF(ABS(SUMIF($B$7:$B$106,B11,$E$7:$E$106)-SUMIF($B$7:$B$106,B11,$F$7:$F$106))<0.5,"OK","ERROR: Dr≠Cr")) -> OK | K11: Effect column: A+/A−/L+/L−/OE+/OE−, as in the course notes. It forces you to think about which side each line goes on.
B12: 2 | C12: Gain: land 10M − 5M = 5M; building 3M − (6M − 5.4M) = 2.4M | D12: P&L – Gain on sale of non-current assets | F12: 7400000 | G12: Rev (OE+) | I12: =IF(B12="","",IF(ABS(SUMIF($B$7:$B$106,B12,$E$7:$E$106)-SUMIF($B$7:$B$106,B12,$F$7:$F$106))<0.5,"OK","ERROR: Dr≠Cr")) -> OK | K12: Cash flow column: only for lines that touch CASH. O = operating, I = investing, F = financing.
B13: 1 | C13: Jan 2019 – jobs created, donation formalized: land at FAIR VALUE 750,000 (not 550,000 tax value) | D13: Land | E13: 750000 | G13: A+ | H13: Non-cash | I13: =IF(B13="","",IF(ABS(SUMIF($B$7:$B$106,B13,$E$7:$E$106)-SUMIF($B$7:$B$106,B13,$F$7:$F$106))<0.5,"OK","ERROR: Dr≠Cr")) -> OK | K13: Entry check turns green when that # balances (debits = credits).
B14: 1 | D14: Deferred income – land donation (grant) | F14: 750000 | G14: L+ | I14: =IF(B14="","",IF(ABS(SUMIF($B$7:$B$106,B14,$E$7:$E$106)-SUMIF($B$7:$B$106,B14,$F$7:$F$106))<0.5,"OK","ERROR: Dr≠Cr")) -> OK | K14: Rule of thumb
B15: 3 | C15: Jan 2019 – demolition 25,000 + levelling & drainage 100,000 → prepare the land for use | D15: Land | E15: 125000 | G15: A+ | I15: =IF(B15="","",IF(ABS(SUMIF($B$7:$B$106,B15,$E$7:$E$106)-SUMIF($B$7:$B$106,B15,$F$7:$F$106))<0.5,"OK","ERROR: Dr≠Cr")) -> OK | K15: Debits: asset ↑, expense ↑, liability ↓, OE ↓
B16: 3 | D16: Cash & cash equivalents | F16: 125000 | G16: A− | H16: I | I16: =IF(B16="","",IF(ABS(SUMIF($B$7:$B$106,B16,$E$7:$E$106)-SUMIF($B$7:$B$106,B16,$F$7:$F$106))<0.5,"OK","ERROR: Dr≠Cr")) -> OK | K16: Credits: asset ↓, revenue ↑, liability ↑, OE ↑
B17: 4a | C17: Jan 2019 – bank loan 600,000 at 5%, 20 annual instalments | D17: Cash & cash equivalents | E17: 600000 | G17: A+ | H17: F | I17: =IF(B17="","",IF(ABS(SUMIF($B$7:$B$106,B17,$E$7:$E$106)-SUMIF($B$7:$B$106,B17,$F$7:$F$106))<0.5,"OK","ERROR: Dr≠Cr")) -> OK | K17: Hint
B18: 4a | D18: Bank loan (5%, 20 annual instalments) | F18: 600000 | G18: L+ | I18: =IF(B18="","",IF(ABS(SUMIF($B$7:$B$106,B18,$E$7:$E$106)-SUMIF($B$7:$B$106,B18,$F$7:$F$106))<0.5,"OK","ERROR: Dr≠Cr")) -> OK | K18: Record everything in the Journal first, then post to the T-Accounts. Mistakes are much easier to spot here than in the Ts.
B19: 4b | C19: 2019 – building 450,000 + management & permits 150,000 + facilities 240,000 + installation 60,000 | D19: Construction in progress (2019) | E19: 900000 | G19: A+ | I19: =IF(B19="","",IF(ABS(SUMIF($B$7:$B$106,B19,$E$7:$E$106)-SUMIF($B$7:$B$106,B19,$F$7:$F$106))<0.5,"OK","ERROR: Dr≠Cr")) -> OK
B20: 4b | D20: Cash & cash equivalents | F20: 900000 | G20: A− | H20: I | I20: =IF(B20="","",IF(ABS(SUMIF($B$7:$B$106,B20,$E$7:$E$106)-SUMIF($B$7:$B$106,B20,$F$7:$F$106))<0.5,"OK","ERROR: Dr≠Cr")) -> OK
B21: 4c | C21: Dec 2019 – interest 600,000 × 5% CAPITALIZED: 20,000 building + 10,000 facilities (2/3 – 1/3 of cost) | D21: Construction in progress (2019) | E21: 30000 | G21: A+ | I21: =IF(B21="","",IF(ABS(SUMIF($B$7:$B$106,B21,$E$7:$E$106)-SUMIF($B$7:$B$106,B21,$F$7:$F$106))<0.5,"OK","ERROR: Dr≠Cr")) -> OK
B22: 4c | D22: Cash & cash equivalents | F22: 30000 | G22: A− | H22: O | I22: =IF(B22="","",IF(ABS(SUMIF($B$7:$B$106,B22,$E$7:$E$106)-SUMIF($B$7:$B$106,B22,$F$7:$F$106))<0.5,"OK","ERROR: Dr≠Cr")) -> OK
B23: 4d | C23: Dec 2019 – 1st loan instalment 600,000 / 20 | D23: Bank loan (5%, 20 annual instalments) | E23: 30000 | G23: L− | I23: =IF(B23="","",IF(ABS(SUMIF($B$7:$B$106,B23,$E$7:$E$106)-SUMIF($B$7:$B$106,B23,$F$7:$F$106))<0.5,"OK","ERROR: Dr≠Cr")) -> OK
B24: 4d | D24: Cash & cash equivalents | F24: 30000 | G24: A− | H24: F | I24: =IF(B24="","",IF(ABS(SUMIF($B$7:$B$106,B24,$E$7:$E$106)-SUMIF($B$7:$B$106,B24,$F$7:$F$106))<0.5,"OK","ERROR: Dr≠Cr")) -> OK
B25: 4e | C25: Jan 2020 – construction finished: building 450 + 150 + 20 interest = 620,000; facilities 240 + 60 + 10 interest = 310,000 | D25: Buildings (old premises + new building) | E25: 620000 | G25: A+ | H25: Non-cash | I25: =IF(B25="","",IF(ABS(SUMIF($B$7:$B$106,B25,$E$7:$E$106)-SUMIF($B$7:$B$106,B25,$F$7:$F$106))<0.5,"OK","ERROR: Dr≠Cr")) -> OK
B26: 4e | D26: Machinery & production facilities | E26: 310000 | G26: A+ | I26: =IF(B26="","",IF(ABS(SUMIF($B$7:$B$106,B26,$E$7:$E$106)-SUMIF($B$7:$B$106,B26,$F$7:$F$106))<0.5,"OK","ERROR: Dr≠Cr")) -> OK
B27: 4e | D27: Construction in progress (2019) | F27: 930000 | G27: A− | I27: =IF(B27="","",IF(ABS(SUMIF($B$7:$B$106,B27,$E$7:$E$106)-SUMIF($B$7:$B$106,B27,$F$7:$F$106))<0.5,"OK","ERROR: Dr≠Cr")) -> OK
B28: 5 | C28: 2020 – relocation 7,000 + transport insurance 1,000 → EXPENSE (staff 450 h × 20 = 9,000 already in salaries) | D28: P&L – Relocation expenses | E28: 8000 | G28: Exp (OE−) | I28: =IF(B28="","",IF(ABS(SUMIF($B$7:$B$106,B28,$E$7:$E$106)-SUMIF($B$7:$B$106,B28,$F$7:$F$106))<0.5,"OK","ERROR: Dr≠Cr")) -> OK
B29: 5 | D29: Cash & cash equivalents | F29: 8000 | G29: A− | H29: O | I29: =IF(B29="","",IF(ABS(SUMIF($B$7:$B$106,B29,$E$7:$E$106)-SUMIF($B$7:$B$106,B29,$F$7:$F$106))<0.5,"OK","ERROR: Dr≠Cr")) -> OK
B30: 6 | C30: 2020 – special maintenance raising productivity 15% → improvement, CAPITALIZE | D30: Machinery & production facilities | E30: 40000 | G30: A+ | I30: =IF(B30="","",IF(ABS(SUMIF($B$7:$B$106,B30,$E$7:$E$106)-SUMIF($B$7:$B$106,B30,$F$7:$F$106))<0.5,"OK","ERROR: Dr≠Cr")) -> OK
B31: 6 | D31: Cash & cash equivalents | F31: 40000 | G31: A− | H31: I | I31: =IF(B31="","",IF(ABS(SUMIF($B$7:$B$106,B31,$E$7:$E$106)-SUMIF($B$7:$B$106,B31,$F$7:$F$106))<0.5,"OK","ERROR: Dr≠Cr")) -> OK
B32: 7a | C32: 2020 – new equipment 200,000 − 2% discount + 600 transport | D32: Machinery & production facilities | E32: 196600 | G32: A+ | I32: =IF(B32="","",IF(ABS(SUMIF($B$7:$B$106,B32,$E$7:$E$106)-SUMIF($B$7:$B$106,B32,$F$7:$F$106))<0.5,"OK","ERROR: Dr≠Cr")) -> OK
B33: 7a | D33: Cash & cash equivalents | F33: 196600 | G33: A− | H33: I | I33: =IF(B33="","",IF(ABS(SUMIF($B$7:$B$106,B33,$E$7:$E$106)-SUMIF($B$7:$B$106,B33,$F$7:$F$106))<0.5,"OK","ERROR: Dr≠Cr")) -> OK
B34: 7b | C34: 2020 – installation by own staff 100 h × (20 direct + 10 overhead) = 3,000; never the 15 profit | D34: Machinery & production facilities | E34: 3000 | G34: A+ | H34: Non-cash | I34: =IF(B34="","",IF(ABS(SUMIF($B$7:$B$106,B34,$E$7:$E$106)-SUMIF($B$7:$B$106,B34,$F$7:$F$106))<0.5,"OK","ERROR: Dr≠Cr")) -> OK
B35: 7b | C35: Salaries were already expensed → move 3,000 out of the P&L into the asset | D35: P&L – Own work capitalized | F35: 3000 | G35: Rev (OE+) | I35: =IF(B35="","",IF(ABS(SUMIF($B$7:$B$106,B35,$E$7:$E$106)-SUMIF($B$7:$B$106,B35,$F$7:$F$106))<0.5,"OK","ERROR: Dr≠Cr")) -> OK
B36: 4f | C36: Dec 2020 – interest 570,000 × 5% → EXPENSE (building already in use) | D36: P&L – Interest expense | E36: 28500 | G36: Exp (OE−) | I36: =IF(B36="","",IF(ABS(SUMIF($B$7:$B$106,B36,$E$7:$E$106)-SUMIF($B$7:$B$106,B36,$F$7:$F$106))<0.5,"OK","ERROR: Dr≠Cr")) -> OK
B37: 4f | D37: Cash & cash equivalents | F37: 28500 | G37: A− | H37: O | I37: =IF(B37="","",IF(ABS(SUMIF($B$7:$B$106,B37,$E$7:$E$106)-SUMIF($B$7:$B$106,B37,$F$7:$F$106))<0.5,"OK","ERROR: Dr≠Cr")) -> OK
B38: 4g | C38: Dec 2020 – 2nd loan instalment | D38: Bank loan (5%, 20 annual instalments) | E38: 30000 | G38: L− | I38: =IF(B38="","",IF(ABS(SUMIF($B$7:$B$106,B38,$E$7:$E$106)-SUMIF($B$7:$B$106,B38,$F$7:$F$106))<0.5,"OK","ERROR: Dr≠Cr")) -> OK
B39: 4g | D39: Cash & cash equivalents | F39: 30000 | G39: A− | H39: F | I39: =IF(B39="","",IF(ABS(SUMIF($B$7:$B$106,B39,$E$7:$E$106)-SUMIF($B$7:$B$106,B39,$F$7:$F$106))<0.5,"OK","ERROR: Dr≠Cr")) -> OK
B40: 4h | C40: Dec 2020 – depreciation: building 620,000 / 20 = 31,000; facilities 310,000 / 10 = 31,000 | D40: P&L – Depreciation expense | E40: 62000 | G40: Exp (OE−) | H40: Non-cash | I40: =IF(B40="","",IF(ABS(SUMIF($B$7:$B$106,B40,$E$7:$E$106)-SUMIF($B$7:$B$106,B40,$F$7:$F$106))<0.5,"OK","ERROR: Dr≠Cr")) -> OK
B41: 4h | D41: Accum. depreciation – Buildings | F41: 31000 | G41: Contra-A+ | I41: =IF(B41="","",IF(ABS(SUMIF($B$7:$B$106,B41,$E$7:$E$106)-SUMIF($B$7:$B$106,B41,$F$7:$F$106))<0.5,"OK","ERROR: Dr≠Cr")) -> OK
B42: 4h | D42: Accum. depreciation – Machinery & facilities | F42: 31000 | G42: Contra-A+ | I42: =IF(B42="","",IF(ABS(SUMIF($B$7:$B$106,B42,$E$7:$E$106)-SUMIF($B$7:$B$106,B42,$F$7:$F$106))<0.5,"OK","ERROR: Dr≠Cr")) -> OK
...

Sheet T-Accounts
B1: T-ACCOUNTS (general ledger)
B2: Company: | D2: =Guide!$C$3 -> Laboratorios Dermolab | L2: Period: | N2: =Guide!$C$4 -> 2018–2021
B5: ASSETS (uses of capital) | L5: OWNERS' EQUITY & LIABILITIES (sources of capital) | W5: Notes & reminders
W6: How to post
B7: Cash & cash equivalents | G7: Marketable securities | M7: Accounts payable | R7: Salaries payable | W7: Write the amount on the correct side and the journal entry # in the grey column next to it, e.g. 1, 2, 3a, CE.
B8: # | C8: Dr (+) | D8: Cr (−) | E8: # | G8: # | H8: Dr (+) | I8: Cr (−) | J8: # | M8: # | N8: Dr (−) | O8: Cr (+) | P8: # | R8: # | S8: Dr (−) | T8: Cr (+) | U8: # | W8: BB = beginning balance (from last period's balance sheet). Leave empty for a new company.
B9: BB | G9: BB | P9: BB | U9: BB | W9: EB = ending balance. It is calculated for you and always sits on the account's normal side.
B10: 2 | C10: 13000000 | D10: 125000 | E10: 3 | W10: Asset side (Uses of capital)
B11: 4a | C11: 600000 | D11: 900000 | E11: 4b | W11: Debit (+) increases, Credit (−) decreases. Normal balance is on the debit side.
D12: 30000 | E12: 4c | W12: Liabilities & OE side (Sources of capital)
D13: 30000 | E13: 4d | W13: Debit (−) decreases, Credit (+) increases. Normal balance is on the credit side.
D14: 8000 | E14: 5 | W14: Contra-assets (accumulated depreciation / amortization)
D15: 40000 | E15: 6 | W15: They sit on the asset side but work like liabilities: depreciation goes on the CREDIT side. Net book value = cost − accumulated depreciation.
D16: 196600 | E16: 7a | W16: Land is NEVER depreciated.
D17: 28500 | E17: 4f | W17: P&L (profit for the period)
D18: 30000 | E18: 4g | W18: This is a temporary owners' equity account. Revenues and gains go on the credit side. Expenses and losses (COGS, salaries, rent used up, depreciation, interest, tax) go on the debit side.
D19: 1000000 | E19: 8a | W19: At the end: closing entry CE = Dr P&L / Cr Retained profits for the net profit. Use # 'CE' so the Income Statement check can ignore it.
D20: 224000 | E20: 9 | W20: Frequent traps
D21: 27000 | E21: 4i | W21: A sale is TWO entries: (a) Dr Cash/A/R, Cr P&L (revenue) and (b) Dr P&L (COGS), Cr Inventory.
D22: 30000 | E22: 4j | W22: Prepaid rent: paying for it is an asset (Dr Prepaid, Cr Cash). Only the part used up in the period is an expense (Dr P&L, Cr Prepaid).
W23: Cash received before delivery is a liability: Deposits from customers.
W24: Buying on credit: Cr Accounts payable, not Cash. Paying later: Dr A/P, Cr Cash, with NO expense.
B25: Tot | C25: =SUM(C9:C24) -> 13600000 | D25: =SUM(D9:D24) -> 2669100 | E25: Tot | G25: Tot | H25: =SUM(H9:H24) -> 0 | I25: =SUM(I9:I24) -> 0 | J25: Tot | M25: Tot | N25: =SUM(N9:N24) -> 0 | O25: =SUM(O9:O24) -> 0 | P25: Tot | R25: Tot | S25: =SUM(S9:S24) -> 0 | T25: =SUM(T9:T24) -> 0 | U25: Tot | W25: Accrued interest, salaries and tax not yet paid: Dr P&L, Cr Interest/Salaries/Taxes payable.
B26: EB | C26: =C25-D25 -> 10930900 | G26: EB | H26: =H25-I25 -> 0 | O26: =O25-N25 -> 0 | P26: EB | T26: =T25-S25 -> 0 | U26: EB | W26: A loan repayment only reduces the loan (Dr Loan, Cr Cash). The interest part is an expense.
W27: A purchase financed by the seller or a mortgage: Dr Land/Building, Cr Mortgage/Obligations (and Cr Cash for any down payment).
B28: Accounts receivable | G28: Inventories | M28: Interest payable | R28: Taxes payable | W28: Dividends: Dr Retained profits, Cr Cash. They are never a P&L expense.
B29: # | C29: Dr (+) | D29: Cr (−) | E29: # | G29: # | H29: Dr (+) | I29: Cr (−) | J29: # | M29: # | N29: Dr (−) | O29: Cr (+) | P29: # | R29: # | S29: Dr (−) | T29: Cr (+) | U29: # | W29: Share issue above par: Cr Share capital (par × shares) + Cr Share premium (the rest).
B30: BB | G30: BB | P30: BB | U30: BB | W30: Checks
W31: Below the T-accounts: total debits must equal total credits. On the Balance Sheet sheet: A = L + OE.
B46: Tot | C46: =SUM(C30:C45) -> 0 | D46: =SUM(D30:D45) -> 0 | E46: Tot | G46: Tot | H46: =SUM(H30:H45) -> 0 | I46: =SUM(I30:I45) -> 0 | J46: Tot | M46: Tot | N46: =SUM(N30:N45) -> 0 | O46: =SUM(O30:O45) -> 0 | P46: Tot | R46: Tot | S46: =SUM(S30:S45) -> 0 | T46: =SUM(T30:T45) -> 0 | U46: Tot
B47: EB | C47: =C46-D46 -> 0 | G47: EB | H47: =H46-I46 -> 0 | O47: =O46-N46 -> 0 | P47: EB | T47: =T46-S46 -> 0 | U47: EB
B49: Prepaid rent / prepaid expenses | G49: Construction in progress (2019) | M49: Deposits from customers (unearned rev.) | R49: Dividends payable
B50: # | C50: Dr (+) | D50: Cr (−) | E50: # | G50: # | H50: Dr (+) | I50: Cr (−) | J50: # | M50: # | N50: Dr (−) | O50: Cr (+) | P50: # | R50: # | S50: Dr (−) | T50: Cr (+) | U50: #
B51: BB | G51: BB | P51: BB | U51: BB
G52: 4b | H52: 900000 | I52: 930000 | J52: 4e
G53: 4c | H53: 30000
B67: Tot | C67: =SUM(C51:C66) -> 0 | D67: =SUM(D51:D66) -> 0 | E67: Tot | G67: Tot | H67: =SUM(H51:H66) -> 930000 | I67: =SUM(I51:I66) -> 930000 | J67: Tot | M67: Tot | N67: =SUM(N51:N66) -> 0 | O67: =SUM(O51:O66) -> 0 | P67: Tot | R67: Tot | S67: =SUM(S51:S66) -> 0 | T67: =SUM(T51:T66) -> 0 | U67: Tot
B68: EB | C68: =C67-D67 -> 0 | G68: EB | H68: =H67-I67 -> 0 | O68: =O67-N67 -> 0 | P68: EB | T68: =T67-S67 -> 0 | U68: EB
B70: Land | G70: Development costs – Baldnessox | M70: Short-term loans / current portion LTD | R70: Deferred income – land donation (grant)
B71: # | C71: Dr (+) | D71: Cr (−) | E71: # | G71: # | H71: Dr (+) | I71: Cr (−) | J71: # | M71: # | N71: Dr (−) | O71: Cr (+) | P71: # | R71: # | S71: Dr (−) | T71: Cr (+) | U71: #
...

Sheet Lists
A1: ='T-Accounts'!$B$7 -> Cash & cash equivalents | B1: A+ | C1: O
A2: ='T-Accounts'!$G$7 -> Marketable securities | B2: A− | C2: I
A3: ='T-Accounts'!$B$28 -> Accounts receivable | B3: L+ | C3: F
A4: ='T-Accounts'!$G$28 -> Inventories | B4: L− | C4: Non-cash
A5: ='T-Accounts'!$B$49 -> Prepaid rent / prepaid expenses | B5: OE+
A6: ='T-Accounts'!$G$49 -> Construction in progress (2019) | B6: OE−
A7: ='T-Accounts'!$B$70 -> Land | B7: Rev (OE+)
A8: ='T-Accounts'!$G$70 -> Development costs – Baldnessox | B8: Exp (OE−)
A9: ='T-Accounts'!$B$91 -> Buildings (old premises + new building) | B9: Contra-A+
A10: ='T-Accounts'!$G$91 -> Accum. depreciation – Buildings | B10: Contra-A−
A11: ='T-Accounts'!$B$112 -> Machinery & production facilities
A12: ='T-Accounts'!$G$112 -> Accum. depreciation – Machinery & facilities
A13: ='T-Accounts'!$B$133 -> Patent – Baldnessox molecule
A14: ='T-Accounts'!$G$133 -> Accum. amortization & impairment – intangibles
A15: ='T-Accounts'!$M$7 -> Accounts payable
A16: ='T-Accounts'!$R$7 -> Salaries payable
A17: ='T-Accounts'!$M$28 -> Interest payable
A18: ='T-Accounts'!$R$28 -> Taxes payable
A19: ='T-Accounts'!$M$49 -> Deposits from customers (unearned rev.)
A20: ='T-Accounts'!$R$49 -> Dividends payable
A21: ='T-Accounts'!$M$70 -> Short-term loans / current portion LTD
A22: ='T-Accounts'!$R$70 -> Deferred income – land donation (grant)
A23: ='T-Accounts'!$M$91 -> Bank loan (5%, 20 annual instalments)
A24: ='T-Accounts'!$R$91 -> Mortgage / obligations on land & bldgs
A25: ='T-Accounts'!$M$112 -> Share capital
A26: ='T-Accounts'!$R$112 -> Share premium
A27: ='T-Accounts'!$M$133 -> Retained profits
A28: ='T-Accounts'!$R$133 -> Profit & loss for the period (P&L)
