Workbook

Sheet Guide
B1: FINANCIAL ACCOUNTING HOMEWORK TEMPLATE
B3: Company name | C3: Maria Soldevila (company) | D3: ← fill in once, every sheet picks it up
B4: Period (e.g. Year 1) | C4: 2011
B5: Currency / units | C5: €
B7: WORKFLOW (do the sheets in this order)
B8: 1. Journal: write every transaction as a journal entry (Dr = Cr). Give each entry a number (1, 2, 3a, 3b, …, CE).
B9: 2. T-Accounts: post each entry to its T-accounts, writing the entry # in the grey # columns. Beginning balances go on the BB row.
B10: 3. Balance Sheet: fills itself from the T-accounts (beginning and ending balances). Check that Assets = L + OE.
B11: 4. Income Statement: type the revenues/expenses from the P&L T-account. Expenses and losses go in as NEGATIVE numbers.
B12: 5. Cash Flow: type each cash movement from the Cash T-account in the direct method. The indirect method fills itself.
B13: 6. CF Worksheet (optional): the course's ΔCash = −ΔA* + ΔL + ΔOE table. Use it to check the indirect method line by line.
B14: 7. Every check cell must say OK in green. A red ERROR tells you how far off you are.
B16: COLOUR LEGEND
B17: 1,000 | C17: Blue text = number you type in (input)
B18: 1,000 | C18: Black text = formula (don't type over it)
B19: Assets | C19: Asset section header (your red)
B20: Account | C20: Asset T-account title
B21: L & OE | C21: Liabilities & owners' equity section header (your blue)
B22: Account | C22: Liability T-account title
B23: Account | C23: Owners' equity T-account title
B24: P&L | C24: Profit & loss for the period (temporary OE account)
B25: I/S | C25: Income statement (green family)
B26: C/F | C26: Cash flow statement (purple, with orange for CFI and cyan for CFF)
B27: OK | C27: Check passed
B28: ERROR | C28: Check failed. The number is the difference.
B30: DEBIT / CREDIT RULES (CN-230-E, T-accounts section)
B31: Account type | C31: Increase | D31: Decrease | E31: Normal balance | F31: Examples
B32: Assets | C32: Debit (left) | D32: Credit (right) | E32: Debit | F32: Cash, A/R, inventory, PPE
B33: Contra-assets | C33: Credit | D33: Debit | E33: Credit | F33: Accumulated depreciation / amortization
B34: Liabilities | C34: Credit | D34: Debit | E34: Credit | F34: A/P, taxes payable, loans
B35: Owners' equity | C35: Credit | D35: Debit | E35: Credit | F35: Share capital, retained profits
B36: P&L: revenues & gains | C36: Credit | E36: Credit | F36: Sales, financial income
B37: P&L: expenses & losses | C37: Debit | E37: Debit | F37: COGS, salaries, depreciation, tax
B38: Every entry: total debits = total credits. A = L + OE always holds. Debit/credit mean LEFT/RIGHT, not +/−.
B39: Closing entry (CE): Dr Profit for the period / Cr Retained profits (net profit). After it the P&L account is zero.
B40: Dividends are NOT an expense: Dr Retained profits / Cr Cash (or Dividends payable).
B42: EXAMPLE JOURNAL ENTRY (from the course note: a €10,000 loan received in cash)
B43: # / Account | C43: Dr | D43: Cr | E43: Effect | F43: Cash flow class
B44: 1 Cash | C44: 10000 | E44: A+ | F44: F (new loan)
B45: 1 Long-term bank loan | D45: 10000 | E45: L+
...

Sheet Corrections
B1: MARIA SOLDEVILA (B) – CORRECTIONS REPORT
B3: 1. About the file you sent (Maria_Soldevila_B.ods)
B4: It contained no 2011 work. It is the (A) solution file unchanged (period 2010, entries 09-1 to CE of 2010). Everything for (B) is therefore built from scratch in this workbook, starting from the professor's Exhibit 1.
B6: 2. Opening balances: Exhibit 1 differs from the earlier (A) solution
C7: Item | D7: (A) solution had | E7: Exhibit 1 (correct)
C8: F&E accumulated depreciation | D8: 0 (assumed no depreciation) | E8: 4,000 (20,000 / 5 years)
C9: Website | D9: 12,000 (assumed no amortization) | E9: 6,000 net (12,000 / 2 years)
C10: Retained profits (2010 net profit) | D10: 120,000 | E10: 110,000
C11: Total assets at Dec 31, 2010 | D11: 670,000 | E11: 660,000
B12: The (A) solution file has been updated to match Exhibit 1.
B14: 3. Manufacturing: where each cost goes (the part you were unsure about)
B15: New T-accounts are needed. Three unused template Ts were renamed: RAW MATERIALS (was 'Prepaid rent'), WORK IN PROGRESS (was 'Other current asset'), MACHINERY + ACCUM. DEPRECIATION – MACHINERY (were 'Software / Accumulated amortization'). Also PAYABLE FOR MACHINERY (was 'Other liability'). 'Inventories' became FINISHED GOODS, and the website moved to the 'Financial investments' T (shown net, as in Exhibit 1).
C16: Event | D16: Entry | E16: Why
C17: Buy raw materials (2) | D17: Dr Raw materials / Cr Accounts payable | E17: It is an asset until it is used.
C18: Use raw materials (4) | D18: Dr WIP / Cr Raw materials | E18: Moves into production. It is NOT an expense.
C19: Production wages & other manufacturing costs (5) | D19: Dr WIP / Cr Cash (162,000) | E19: Product cost. It becomes an expense only when the mixers are SOLD.
C20: Machinery depreciation (7) | D20: Dr WIP / Cr Accum. depreciation – Machinery (40,000) | E20: The uncle's instruction: production depreciation is included in the product cost.
C21: Mixers finished (8) | D21: Dr Finished goods / Cr WIP (444,000) | E21: 600 units → 740 per unit. No WIP left at year end.
C22: Mixers sold (9) | D22: Dr AR / Cr P&L Sales (944,000) and Dr P&L COGS / Cr Finished goods (439,000) | E22: FIFO: the 40 old units at 800 first, then 550 at 740. Ending stock is 50 × 740 = 37,000.
C23: Selling & admin. costs (6), building/website depreciation (16) | D23: Dr P&L directly | E23: These are period expenses, not product costs.
B25: 4. Other items that are easy to miss
B26: • Machinery (1): only 80,000 is paid in January. The other 160,000 is a liability (Payable for machinery) until it is paid in September. Both payments are INVESTING cash flows.
B27: • Dividends (11): Dr Retained profits / Cr Cash. They are NOT a P&L expense. Cash flow: FINANCING.
B28: • Sale of old furniture (12): remove BOTH the cost (20,000) and its accumulated depreciation (4,000). Book value 16,000 − price 9,000 = loss 7,000. The 9,000 cash is INVESTING.
B29: • New furniture (13): an asset (Dr F&E 25,000). Bought at the end of December, so no depreciation in 2011.
B30: • Bad debts (14): Dr P&L bad debt expense 10,000 / Cr Accounts receivable. It is not a cash flow. AR is shown net of expected defaults.
B31: • Marketable securities (15): market 21,000 > cost 20,000. By prudence (lower of cost or market) the 1,000 unrealized gain is NOT recorded. Keep them at 20,000.
B32: • Depreciation (16): building 5,000 and website 6,000 go straight to the P&L. The website is then fully amortized.
B33: • Taxes: ignored, as the uncle asked.
B34: • Indirect cash flow: add back ALL depreciation (51,000 incl. the 40,000 inside product cost). The inventory changes then take care of the part still sitting in stock.
B36: 5. Results 2011
B37: Income statement: sales 944,000 − COGS 439,000 = gross profit 505,000; − S&A 150,000 − bad debts 10,000 − D&A 11,000 − loss on sale 7,000 = NET PROFIT 327,000.
... B44: • The deferred 160,000 for the machinery was paid at the end of September as agreed.

Sheet Journal
B1: JOURNAL ENTRIES
B2: Company: | C2: =Guide!$C$3 -> Maria Soldevila (company) | E2: Period: | F2: =Guide!$C$4 -> 2011
C4: TOTAL | E4: =SUM(E7:E106) -> 4614000 | F4: =SUM(F7:F106) -> 4614000 | G4: =IF(ABS(E4-F4)<0.5,"OK","ERROR: "&TEXT(E4-F4,"#,##0")) -> OK
B6: # | C6: Description of transaction | D6: Account (pick from list or type) | E6: Dr | F6: Cr | G6: Effect | H6: Cash flow | I6: Entry check | K6: Notes & reminders
B7: 1a | C7: Machinery installed: 240,000; 1/3 paid in cash, 2/3 deferred to end of September | D7: Machinery | E7: 240000 | G7: A+ | I7: =IF(B7="","",IF(ABS(SUMIF($B$7:$B$106,B7,$E$7:$E$106)-SUMIF($B$7:$B$106,B7,$F$7:$F$106))<0.5,"OK","ERROR: Dr≠Cr")) -> OK | K7: How to use
B8: 1a | D8: Cash & cash equivalents | F8: 80000 | G8: A− | H8: I | I8: =IF(B8="","",IF(ABS(SUMIF($B$7:$B$106,B8,$E$7:$E$106)-SUMIF($B$7:$B$106,B8,$F$7:$F$106))<0.5,"OK","ERROR: Dr≠Cr")) -> OK | K8: One line per account touched. All lines of the same transaction share the same # (e.g. 3a, 3a).
B9: 1a | D9: Payable for machinery | F9: 160000 | G9: L+ | I9: =IF(B9="","",IF(ABS(SUMIF($B$7:$B$106,B9,$E$7:$E$106)-SUMIF($B$7:$B$106,B9,$F$7:$F$106))<0.5,"OK","ERROR: Dr≠Cr")) -> OK | K9: Write the debit lines first, then the credit lines (Dr Cash / Cr Loan).
B10: 1b | C10: End of September: deferred 2/3 of the machinery paid | D10: Payable for machinery | E10: 160000 | G10: L− | I10: =IF(B10="","",IF(ABS(SUMIF($B$7:$B$106,B10,$E$7:$E$106)-SUMIF($B$7:$B$106,B10,$F$7:$F$106))<0.5,"OK","ERROR: Dr≠Cr")) -> OK | K10: For P&L lines, write e.g. 'P&L – Sales revenue' or 'P&L – Salaries expense' so the Income Statement is easy to build.
B11: 1b | D11: Cash & cash equivalents | F11: 160000 | G11: A− | H11: I | I11: =IF(B11="","",IF(ABS(SUMIF($B$7:$B$106,B11,$E$7:$E$106)-SUMIF($B$7:$B$106,B11,$F$7:$F$106))<0.5,"OK","ERROR: Dr≠Cr")) -> OK | K11: Effect column: A+/A−/L+/L−/OE+/OE−, as in the course notes. It forces you to think about which side each line goes on.
B12: 2 | C12: Raw materials bought on credit | D12: Raw materials inventory | E12: 270000 | G12: A+ | I12: =IF(B12="","",IF(ABS(SUMIF($B$7:$B$106,B12,$E$7:$E$106)-SUMIF($B$7:$B$106,B12,$F$7:$F$106))<0.5,"OK","ERROR: Dr≠Cr")) -> OK | K12: Cash flow column: only for lines that touch CASH. O = operating, I = investing, F = financing.
B13: 2 | D13: Accounts payable | F13: 270000 | G13: L+ | I13: =IF(B13="","",IF(ABS(SUMIF($B$7:$B$106,B13,$E$7:$E$106)-SUMIF($B$7:$B$106,B13,$F$7:$F$106))<0.5,"OK","ERROR: Dr≠Cr")) -> OK | K13: Entry check turns green when that # balances (debits = credits).
B14: 3 | C14: Payments to raw-material suppliers | D14: Accounts payable | E14: 250000 | G14: L− | I14: =IF(B14="","",IF(ABS(SUMIF($B$7:$B$106,B14,$E$7:$E$106)-SUMIF($B$7:$B$106,B14,$F$7:$F$106))<0.5,"OK","ERROR: Dr≠Cr")) -> OK | K14: Rule of thumb
B15: 3 | D15: Cash & cash equivalents | F15: 250000 | G15: A− | H15: O | I15: =IF(B15="","",IF(ABS(SUMIF($B$7:$B$106,B15,$E$7:$E$106)-SUMIF($B$7:$B$106,B15,$F$7:$F$106))<0.5,"OK","ERROR: Dr≠Cr")) -> OK | K15: Debits: asset ↑, expense ↑, liability ↓, OE ↓
B16: 4 | C16: Raw materials moved into production (NOT an expense yet) | D16: Work in progress (WIP) | E16: 242000 | G16: A+ | I16: =IF(B16="","",IF(ABS(SUMIF($B$7:$B$106,B16,$E$7:$E$106)-SUMIF($B$7:$B$106,B16,$F$7:$F$106))<0.5,"OK","ERROR: Dr≠Cr")) -> OK | K16: Credits: asset ↓, revenue ↑, liability ↑, OE ↑
B17: 4 | D17: Raw materials inventory | F17: 242000 | G17: A− | I17: =IF(B17="","",IF(ABS(SUMIF($B$7:$B$106,B17,$E$7:$E$106)-SUMIF($B$7:$B$106,B17,$F$7:$F$106))<0.5,"OK","ERROR: Dr≠Cr")) -> OK | K17: Hint
B18: 5 | C18: Manufacturing wages 80,000 + other manufacturing costs 82,000 → product cost | D18: Work in progress (WIP) | E18: 162000 | G18: A+ | I18: =IF(B18="","",IF(ABS(SUMIF($B$7:$B$106,B18,$E$7:$E$106)-SUMIF($B$7:$B$106,B18,$F$7:$F$106))<0.5,"OK","ERROR: Dr≠Cr")) -> OK | K18: Record everything in the Journal first, then post to the T-Accounts. Mistakes are much easier to spot here than in the Ts.
B19: 5 | D19: Cash & cash equivalents | F19: 162000 | G19: A− | H19: O | I19: =IF(B19="","",IF(ABS(SUMIF($B$7:$B$106,B19,$E$7:$E$106)-SUMIF($B$7:$B$106,B19,$F$7:$F$106))<0.5,"OK","ERROR: Dr≠Cr")) -> OK
B20: 6 | C20: Selling & admin. expenses (incl. 100,000 personnel) → period expense | D20: P&L – Selling & admin. expenses | E20: 150000 | G20: Exp (OE−) | I20: =IF(B20="","",IF(ABS(SUMIF($B$7:$B$106,B20,$E$7:$E$106)-SUMIF($B$7:$B$106,B20,$F$7:$F$106))<0.5,"OK","ERROR: Dr≠Cr")) -> OK
B21: 6 | D21: Cash & cash equivalents | F21: 150000 | G21: A− | H21: O | I21: =IF(B21="","",IF(ABS(SUMIF($B$7:$B$106,B21,$E$7:$E$106)-SUMIF($B$7:$B$106,B21,$F$7:$F$106))<0.5,"OK","ERROR: Dr≠Cr")) -> OK
B22: 7 | C22: Machinery depreciation 240,000 / 6 years → product cost (item 7) | D22: Work in progress (WIP) | E22: 40000 | G22: A+ | H22: Non-cash | I22: =IF(B22="","",IF(ABS(SUMIF($B$7:$B$106,B22,$E$7:$E$106)-SUMIF($B$7:$B$106,B22,$F$7:$F$106))<0.5,"OK","ERROR: Dr≠Cr")) -> OK
B23: 7 | D23: Accum. depreciation – Machinery | F23: 40000 | G23: Contra-A+ | I23: =IF(B23="","",IF(ABS(SUMIF($B$7:$B$106,B23,$E$7:$E$106)-SUMIF($B$7:$B$106,B23,$F$7:$F$106))<0.5,"OK","ERROR: Dr≠Cr")) -> OK
B24: 8 | C24: 600 mixers finished (242,000 + 162,000 + 40,000 = 444,000 → 740/unit); no WIP left | D24: Finished goods inventory | E24: 444000 | G24: A+ | I24: =IF(B24="","",IF(ABS(SUMIF($B$7:$B$106,B24,$E$7:$E$106)-SUMIF($B$7:$B$106,B24,$F$7:$F$106))<0.5,"OK","ERROR: Dr≠Cr")) -> OK
B25: 8 | D25: Work in progress (WIP) | F25: 444000 | G25: A− | I25: =IF(B25="","",IF(ABS(SUMIF($B$7:$B$106,B25,$E$7:$E$106)-SUMIF($B$7:$B$106,B25,$F$7:$F$106))<0.5,"OK","ERROR: Dr≠Cr")) -> OK
B26: 9a | C26: 590 mixers sold on credit | D26: Accounts receivable | E26: 944000 | G26: A+ | I26: =IF(B26="","",IF(ABS(SUMIF($B$7:$B$106,B26,$E$7:$E$106)-SUMIF($B$7:$B$106,B26,$F$7:$F$106))<0.5,"OK","ERROR: Dr≠Cr")) -> OK
B27: 9a | D27: P&L – Sales revenue | F27: 944000 | G27: Rev (OE+) | I27: =IF(B27="","",IF(ABS(SUMIF($B$7:$B$106,B27,$E$7:$E$106)-SUMIF($B$7:$B$106,B27,$F$7:$F$106))<0.5,"OK","ERROR: Dr≠Cr")) -> OK
B28: 9b | C28: COGS (FIFO): 40 × 800 + 550 × 740 = 439,000 | D28: P&L – COGS expense | E28: 439000 | G28: Exp (OE−) | I28: =IF(B28="","",IF(ABS(SUMIF($B$7:$B$106,B28,$E$7:$E$106)-SUMIF($B$7:$B$106,B28,$F$7:$F$106))<0.5,"OK","ERROR: Dr≠Cr")) -> OK
B29: 9b | D29: Finished goods inventory | F29: 439000 | G29: A− | I29: =IF(B29="","",IF(ABS(SUMIF($B$7:$B$106,B29,$E$7:$E$106)-SUMIF($B$7:$B$106,B29,$F$7:$F$106))<0.5,"OK","ERROR: Dr≠Cr")) -> OK
B30: 10 | C30: Collections from customers | D30: Cash & cash equivalents | E30: 850000 | G30: A+ | H30: O | I30: =IF(B30="","",IF(ABS(SUMIF($B$7:$B$106,B30,$E$7:$E$106)-SUMIF($B$7:$B$106,B30,$F$7:$F$106))<0.5,"OK","ERROR: Dr≠Cr")) -> OK
B31: 10 | D31: Accounts receivable | F31: 850000 | G31: A− | I31: =IF(B31="","",IF(ABS(SUMIF($B$7:$B$106,B31,$E$7:$E$106)-SUMIF($B$7:$B$106,B31,$F$7:$F$106))<0.5,"OK","ERROR: Dr≠Cr")) -> OK
B32: 11 | C32: Dividends approved and paid (NOT an expense) | D32: Retained profits | E32: 30000 | G32: OE− | I32: =IF(B32="","",IF(ABS(SUMIF($B$7:$B$106,B32,$E$7:$E$106)-SUMIF($B$7:$B$106,B32,$F$7:$F$106))<0.5,"OK","ERROR: Dr≠Cr")) -> OK
B33: 11 | D33: Cash & cash equivalents | F33: 30000 | G33: A− | H33: F | I33: =IF(B33="","",IF(ABS(SUMIF($B$7:$B$106,B33,$E$7:$E$106)-SUMIF($B$7:$B$106,B33,$F$7:$F$106))<0.5,"OK","ERROR: Dr≠Cr")) -> OK
B34: 12 | C34: Old furniture sold for 9,000; book value 20,000 − 4,000 = 16,000 → loss 7,000 | D34: Cash & cash equivalents | E34: 9000 | G34: A+ | H34: I | I34: =IF(B34="","",IF(ABS(SUMIF($B$7:$B$106,B34,$E$7:$E$106)-SUMIF($B$7:$B$106,B34,$F$7:$F$106))<0.5,"OK","ERROR: Dr≠Cr")) -> OK
B35: 12 | D35: Accum. depreciation – Furn. & equip. | E35: 4000 | G35: Contra-A− | I35: =IF(B35="","",IF(ABS(SUMIF($B$7:$B$106,B35,$E$7:$E$106)-SUMIF($B$7:$B$106,B35,$F$7:$F$106))<0.5,"OK","ERROR: Dr≠Cr")) -> OK
B36: 12 | D36: P&L – Loss on sale of furniture & equipment | E36: 7000 | G36: Exp (OE−) | I36: =IF(B36="","",IF(ABS(SUMIF($B$7:$B$106,B36,$E$7:$E$106)-SUMIF($B$7:$B$106,B36,$F$7:$F$106))<0.5,"OK","ERROR: Dr≠Cr")) -> OK
B37: 12 | D37: Furniture & equipment | F37: 20000 | G37: A− | I37: =IF(B37="","",IF(ABS(SUMIF($B$7:$B$106,B37,$E$7:$E$106)-SUMIF($B$7:$B$106,B37,$F$7:$F$106))<0.5,"OK","ERROR: Dr≠Cr")) -> OK
B38: 13 | C38: New furniture & equipment bought for cash | D38: Furniture & equipment | E38: 25000 | G38: A+ | I38: =IF(B38="","",IF(ABS(SUMIF($B$7:$B$106,B38,$E$7:$E$106)-SUMIF($B$7:$B$106,B38,$F$7:$F$106))<0.5,"OK","ERROR: Dr≠Cr")) -> OK
B39: 13 | D39: Cash & cash equivalents | F39: 25000 | G39: A− | H39: I | I39: =IF(B39="","",IF(ABS(SUMIF($B$7:$B$106,B39,$E$7:$E$106)-SUMIF($B$7:$B$106,B39,$F$7:$F$106))<0.5,"OK","ERROR: Dr≠Cr")) -> OK
B40: 14 | C40: Uncollectible receivables written down (AR shown net) | D40: P&L – Bad debt expense | E40: 10000 | G40: Exp (OE−) | H40: Non-cash | I40: =IF(B40="","",IF(ABS(SUMIF($B$7:$B$106,B40,$E$7:$E$106)-SUMIF($B$7:$B$106,B40,$F$7:$F$106))<0.5,"OK","ERROR: Dr≠Cr")) -> OK
B41: 14 | D41: Accounts receivable | F41: 10000 | G41: A− | I41: =IF(B41="","",IF(ABS(SUMIF($B$7:$B$106,B41,$E$7:$E$106)-SUMIF($B$7:$B$106,B41,$F$7:$F$106))<0.5,"OK","ERROR: Dr≠Cr")) -> OK
B42: 15 | C42: Securities: market 21,000 > cost 20,000 → NO entry (prudence / lower of cost or market) | D42: (no entry) | I42: =IF(B42="","",IF(ABS(SUMIF($B$7:$B$106,B42,$E$7:$E$106)-SUMIF($B$7:$B$106,B42,$F$7:$F$106))<0.5,"OK","ERROR: Dr≠Cr")) -> OK
...

Sheet T-Accounts
B1: T-ACCOUNTS (general ledger)
B2: Company: | D2: =Guide!$C$3 -> Maria Soldevila (company) | L2: Period: | N2: =Guide!$C$4 -> 2011
B5: ASSETS (uses of capital) | L5: OWNERS' EQUITY & LIABILITIES (sources of capital) | W5: Notes & reminders
W6: How to post
B7: Cash & cash equivalents | G7: Marketable securities | M7: Accounts payable | R7: Salaries payable | W7: Write the amount on the correct side and the journal entry # in the grey column next to it, e.g. 1, 2, 3a, CE.
B8: # | C8: Dr (+) | D8: Cr (−) | E8: # | G8: # | H8: Dr (+) | I8: Cr (−) | J8: # | M8: # | N8: Dr (−) | O8: Cr (+) | P8: # | R8: # | S8: Dr (−) | T8: Cr (+) | U8: # | W8: BB = beginning balance (from last period's balance sheet). Leave empty for a new company.
B9: BB | C9: 101000 | G9: BB | H9: 20000 | O9: 50000 | P9: BB | U9: BB | W9: EB = ending balance. It is calculated for you and always sits on the account's normal side.
B10: 10 | C10: 850000 | D10: 80000 | E10: 1a | M10: 3 | N10: 250000 | O10: 270000 | P10: 2 | W10: Asset side (Uses of capital)
B11: 12 | C11: 9000 | D11: 160000 | E11: 1b | W11: Debit (+) increases, Credit (−) decreases. Normal balance is on the debit side.
D12: 250000 | E12: 3 | W12: Liabilities & OE side (Sources of capital)
D13: 162000 | E13: 5 | W13: Debit (−) decreases, Credit (+) increases. Normal balance is on the credit side.
D14: 150000 | E14: 6 | W14: Contra-assets (accumulated depreciation / amortization)
D15: 30000 | E15: 11 | W15: They sit on the asset side but work like liabilities: depreciation goes on the CREDIT side. Net book value = cost − accumulated depreciation.
D16: 25000 | E16: 13 | W16: Land is NEVER depreciated.
W17: P&L (profit for the period)
W18: This is a temporary owners' equity account. Revenues and gains go on the credit side. Expenses and losses (COGS, salaries, rent used up, depreciation, interest, tax) go on the debit side.
W19: At the end: closing entry CE = Dr P&L / Cr Retained profits for the net profit. Use # 'CE' so the Income Statement check can ignore it.
W20: Frequent traps
W21: A sale is TWO entries: (a) Dr Cash/A/R, Cr P&L (revenue) and (b) Dr P&L (COGS), Cr Inventory.
W22: Prepaid rent: paying for it is an asset (Dr Prepaid, Cr Cash). Only the part used up in the period is an expense (Dr P&L, Cr Prepaid).
W23: Cash received before delivery is a liability: Deposits from customers.
W24: Buying on credit: Cr Accounts payable, not Cash. Paying later: Dr A/P, Cr Cash, with NO expense.
B25: Tot | C25: =SUM(C9:C24) -> 960000 | D25: =SUM(D9:D24) -> 857000 | E25: Tot | G25: Tot | H25: =SUM(H9:H24) -> 20000 | I25: =SUM(I9:I24) -> 0 | J25: Tot | M25: Tot | N25: =SUM(N9:N24) -> 250000 | O25: =SUM(O9:O24) -> 320000 | P25: Tot | R25: Tot | S25: =SUM(S9:S24) -> 0 | T25: =SUM(T9:T24) -> 0 | U25: Tot | W25: Accrued interest, salaries and tax not yet paid: Dr P&L, Cr Interest/Salaries/Taxes payable.
B26: EB | C26: =C25-D25 -> 103000 | G26: EB | H26: =H25-I25 -> 20000 | O26: =O25-N25 -> 70000 | P26: EB | T26: =T25-S25 -> 0 | U26: EB | W26: A loan repayment only reduces the loan (Dr Loan, Cr Cash). The interest part is an expense.
W27: A purchase financed by the seller or a mortgage: Dr Land/Building, Cr Mortgage/Obligations (and Cr Cash for any down payment).
B28: Accounts receivable | G28: Finished goods inventory | M28: Interest payable | R28: Taxes payable | W28: Dividends: Dr Retained profits, Cr Cash. They are never a P&L expense.
B29: # | C29: Dr (+) | D29: Cr (−) | E29: # | G29: # | H29: Dr (+) | I29: Cr (−) | J29: # | M29: # | N29: Dr (−) | O29: Cr (+) | P29: # | R29: # | S29: Dr (−) | T29: Cr (+) | U29: # | W29: Share issue above par: Cr Share capital (par × shares) + Cr Share premium (the rest).
B30: BB | C30: 90000 | G30: BB | H30: 32000 | P30: BB | U30: BB | W30: Checks
B31: 9a | C31: 944000 | D31: 850000 | E31: 10 | G31: 8 | H31: 444000 | I31: 439000 | J31: 9b | W31: Below the T-accounts: total debits must equal total credits. On the Balance Sheet sheet: A = L + OE.
D32: 10000 | E32: 14
B46: Tot | C46: =SUM(C30:C45) -> 1034000 | D46: =SUM(D30:D45) -> 860000 | E46: Tot | G46: Tot | H46: =SUM(H30:H45) -> 476000 | I46: =SUM(I30:I45) -> 439000 | J46: Tot | M46: Tot | N46: =SUM(N30:N45) -> 0 | O46: =SUM(O30:O45) -> 0 | P46: Tot | R46: Tot | S46: =SUM(S30:S45) -> 0 | T46: =SUM(T30:T45) -> 0 | U46: Tot
B47: EB | C47: =C46-D46 -> 174000 | G47: EB | H47: =H46-I46 -> 37000 | O47: =O46-N46 -> 0 | P47: EB | T47: =T46-S46 -> 0 | U47: EB
B49: Raw materials inventory | G49: Work in progress (WIP) | M49: Deposits from customers (unearned rev.) | R49: Dividends payable
B50: # | C50: Dr (+) | D50: Cr (−) | E50: # | G50: # | H50: Dr (+) | I50: Cr (−) | J50: # | M50: # | N50: Dr (−) | O50: Cr (+) | P50: # | R50: # | S50: Dr (−) | T50: Cr (+) | U50: #
B51: BB | G51: BB | P51: BB | U51: BB
B52: 2 | C52: 270000 | D52: 242000 | E52: 4 | G52: 4 | H52: 242000 | I52: 444000 | J52: 8
G53: 5 | H53: 162000
G54: 7 | H54: 40000
B67: Tot | C67: =SUM(C51:C66) -> 270000 | D67: =SUM(D51:D66) -> 242000 | E67: Tot | G67: Tot | H67: =SUM(H51:H66) -> 444000 | I67: =SUM(I51:I66) -> 444000 | J67: Tot | M67: Tot | N67: =SUM(N51:N66) -> 0 | O67: =SUM(O51:O66) -> 0 | P67: Tot | R67: Tot | S67: =SUM(S51:S66) -> 0 | T67: =SUM(T51:T66) -> 0 | U67: Tot
B68: EB | C68: =C67-D67 -> 28000 | G68: EB | H68: =H67-I67 -> 0 | O68: =O67-N67 -> 0 | P68: EB | T68: =T67-S67 -> 0 | U68: EB
...

Sheet Balance Sheet
B1: BALANCE SHEET (statement of financial position)
B2: =Guide!$C$3&" – "&Guide!$C$4&" (in "&Guide!$C$5&")" -> Maria Soldevila (company) – 2011 (in €)
C4: 31 Dec 2010 | D4: 31 Dec 2011 | E4: Change (Δ) | G4: Notes & reminders
B5: ASSETS (uses of capital) | G5: This sheet is 100% formulas
B6: Current assets | G6: Everything comes from the T-Accounts sheet: Beginning = BB row, Ending = EB row. Don't type here. If a number is wrong, fix the T-account.
B7: =" "&'T-Accounts'!$B$7 -> Cash & cash equivalents | C7: ='T-Accounts'!$C$9 -> 101000 | D7: ='T-Accounts'!$C$26 -> 103000 | E7: =D7-C7 -> 2000 | G7: Account names come from the T-account titles, so renaming a T renames the line here.
B8: =" "&'T-Accounts'!$G$7 -> Marketable securities | C8: ='T-Accounts'!$H$9 -> 20000 | D8: ='T-Accounts'!$H$26 -> 20000 | E8: =D8-C8 -> 0 | G8: Classification (CN-231-E)
B9: =" "&'T-Accounts'!$B$28 -> Accounts receivable | C9: ='T-Accounts'!$C$30 -> 90000 | D9: ='T-Accounts'!$C$47 -> 174000 | E9: =D9-C9 -> 84000 | G9: Current = cash, or turned into cash / sold / used up within 12 months or the operating cycle, whichever is longer.
B10: =" "&'T-Accounts'!$G$28 -> Finished goods inventory | C10: ='T-Accounts'!$H$30 -> 32000 | D10: ='T-Accounts'!$H$47 -> 37000 | E10: =D10-C10 -> 5000 | G10: Cash & cash equivalents: cash + investments maturing in under 3 months.
B11: =" "&'T-Accounts'!$B$49 -> Raw materials inventory | C11: ='T-Accounts'!$C$51 -> 0 | D11: ='T-Accounts'!$C$68 -> 28000 | E11: =D11-C11 -> 28000 | G11: Marketable securities: 3 to 12 months (current). Longer = financial investments (non-current).
B12: =" "&'T-Accounts'!$G$49 -> Work in progress (WIP) | C12: ='T-Accounts'!$H$51 -> 0 | D12: ='T-Accounts'!$H$68 -> 0 | E12: =D12-C12 -> 0 | G12: Current portion of a long-term loan (next repayment) goes in current liabilities.
B13: Total current assets (CA) | C13: =C7+C8+C9+C10+C11+C12 -> 243000 | D13: =D7+D8+D9+D10+D11+D12 -> 362000 | E13: =E7+E8+E9+E10+E11+E12 -> 119000 | G13: PPE and intangibles are shown at cost less accumulated depreciation/amortization. Land is not depreciated.
B14: Non-current assets | G14: Profit for the period line
B15: =" "&'T-Accounts'!$B$70 -> Land | C15: ='T-Accounts'!$C$72 -> 300000 | D15: ='T-Accounts'!$C$89 -> 300000 | E15: =D15-C15 -> 0 | G15: Shows 0 once you have recorded the closing entry (net profit moved into Retained profits). If you have not, the net profit shows here. The total is correct either way.
B16: =" "&'T-Accounts'!$B$91 -> Buildings | C16: ='T-Accounts'!$C$93 -> 100000 | D16: ='T-Accounts'!$C$110 -> 100000 | E16: =D16-C16 -> 0 | G16: Presentation
B17: =" Less: "&'T-Accounts'!$G$91 -> Less: Accum. depreciation – Buildings | C17: =-'T-Accounts'!$I$93 -> -5000 | D17: =-'T-Accounts'!$I$110 -> -10000 | E17: =D17-C17 -> -5000 | G17: This layout is the stakeholder view (A = L + OE). Continental Europe shows NCA first. UK/Ireland uses net assets (NCA + CA − CL − NCL = OE). The numbers are the same in all three.
B18: Buildings, net | C18: =C16+C17 -> 95000 | D18: =D16+D17 -> 90000 | E18: =E16+E17 -> -5000 | G18: Checks
B19: =" "&'T-Accounts'!$B$112 -> Furniture & equipment | C19: ='T-Accounts'!$C$114 -> 20000 | D19: ='T-Accounts'!$C$131 -> 25000 | E19: =D19-C19 -> 5000 | G19: Both check cells must be green in BOTH columns. If only Ending fails, a transaction is posted on one side only.
B20: =" Less: "&'T-Accounts'!$G$112 -> Less: Accum. depreciation – Furn. & equip. | C20: =-'T-Accounts'!$I$114 -> -4000 | D20: =-'T-Accounts'!$I$131 -> 0 | E20: =D20-C20 -> 4000
B21: Furniture & equipment, net | C21: =C19+C20 -> 16000 | D21: =D19+D20 -> 25000 | E21: =E19+E20 -> 9000
B22: =" "&'T-Accounts'!$B$133 -> Machinery | C22: ='T-Accounts'!$C$135 -> 0 | D22: ='T-Accounts'!$C$152 -> 240000 | E22: =D22-C22 -> 240000
B23: =" Less: "&'T-Accounts'!$G$133 -> Less: Accum. depreciation – Machinery | C23: =-'T-Accounts'!$I$135 -> 0 | D23: =-'T-Accounts'!$I$152 -> -40000 | E23: =D23-C23 -> -40000
B24: Machinery, net | C24: =C22+C23 -> 0 | D24: =D22+D23 -> 200000 | E24: =E22+E23 -> 200000
B25: =" "&'T-Accounts'!$G$70 -> Website (net of amortization) | C25: ='T-Accounts'!$H$72 -> 6000 | D25: ='T-Accounts'!$H$89 -> 0 | E25: =D25-C25 -> -6000
B26: Total non-current assets (NCA) | C26: =C15+C18+C21+C24+C25 -> 417000 | D26: =D15+D18+D21+D24+D25 -> 615000 | E26: =E15+E18+E21+E24+E25 -> 198000
B27: TOTAL ASSETS | C27: =C13+C26 -> 660000 | D27: =D13+D26 -> 977000 | E27: =E13+E26 -> 317000
B29: OWNERS' EQUITY & LIABILITIES (sources of capital)
B30: Owners' equity
B31: =" "&'T-Accounts'!$M$112 -> Share capital | C31: ='T-Accounts'!$O$114 -> 500000 | D31: ='T-Accounts'!$O$131 -> 500000 | E31: =D31-C31 -> 0
B32: =" "&'T-Accounts'!$R$112 -> Share premium | C32: ='T-Accounts'!$T$114 -> 0 | D32: ='T-Accounts'!$T$131 -> 0 | E32: =D32-C32 -> 0
B33: =" "&'T-Accounts'!$M$133 -> Retained profits | C33: ='T-Accounts'!$O$135 -> 110000 | D33: ='T-Accounts'!$O$152 -> 407000 | E33: =D33-C33 -> 297000
B34: =" "&'T-Accounts'!$R$133 -> Profit & loss for the period (P&L) | C34: ='T-Accounts'!$T$135 -> 0 | D34: ='T-Accounts'!$T$152 -> 0 | E34: =D34-C34 -> 0
B35: Total owners' equity (OE) | C35: =C31+C32+C33+C34 -> 610000 | D35: =D31+D32+D33+D34 -> 907000 | E35: =E31+E32+E33+E34 -> 297000
B36: Non-current liabilities
B37: =" "&'T-Accounts'!$M$91 -> Long-term bank loan | C37: ='T-Accounts'!$O$93 -> 0 | D37: ='T-Accounts'!$O$110 -> 0 | E37: =D37-C37 -> 0
B38: =" "&'T-Accounts'!$R$91 -> Mortgage / obligations on land & bldgs | C38: ='T-Accounts'!$T$93 -> 0 | D38: ='T-Accounts'!$T$110 -> 0 | E38: =D38-C38 -> 0
B39: Total non-current liabilities (NCL) | C39: =C37+C38 -> 0 | D39: =D37+D38 -> 0 | E39: =E37+E38 -> 0
B40: Current liabilities
B41: =" "&'T-Accounts'!$M$7 -> Accounts payable | C41: ='T-Accounts'!$O$9 -> 50000 | D41: ='T-Accounts'!$O$26 -> 70000 | E41: =D41-C41 -> 20000
B42: =" "&'T-Accounts'!$R$7 -> Salaries payable | C42: ='T-Accounts'!$T$9 -> 0 | D42: ='T-Accounts'!$T$26 -> 0 | E42: =D42-C42 -> 0
...

Sheet Income Statement
B1: INCOME STATEMENT (P&L)
B2: =Guide!$C$3&" – for the period "&Guide!$C$4&" (in "&Guide!$C$5&")" -> Maria Soldevila (company) – for the period 2011 (in €)
C4: Amount | D4: % of sales | F4: Notes & reminders
B5: Sales revenue (590 mixers on credit) | C5: 944000 | D5: =IF(OR($C$5=0,C5=""),"",C5/$C$5) -> 1 | F5: Sign convention
B6: − Cost of goods sold (FIFO: 40 × 800 + 550 × 740) | C6: -439000 | D6: =IF(OR($C$5=0,C6=""),"",C6/$C$5) -> -0.46504237 | F6: Type revenues and gains as POSITIVE and expenses and losses as NEGATIVE (e.g. COGS −781), as in the course notes. Subtotals simply add up.
B7: = Gross profit (margin) | C7: =C5+C6 -> 505000 | D7: =IF(OR($C$5=0,C7=""),"",C7/$C$5) -> 0.53495763 | F7: Where the numbers come from
B8: − Selling & administrative expenses (incl. 100,000 personnel) | C8: -150000 | D8: =IF(OR($C$5=0,C8=""),"",C8/$C$5) -> -0.15889831 | F8: Every line is one of the entries on the P&L T-account: credits are revenues, debits are expenses.
B9: − Administration expenses | D9: =IF(OR($C$5=0,C9=""),"",C9/$C$5) | F9: Only use the lines the case needs and leave the rest empty (they show '-').
B10: − Research & development expenses | D10: =IF(OR($C$5=0,C10=""),"",C10/$C$5) | F10: Format (CN-232-E)
B11: − Salaries expense (if not split by function) | D11: =IF(OR($C$5=0,C11=""),"",C11/$C$5) | F11: By function (Table 1): COGS, marketing & selling, administration, R&D.
B12: − Rent expense | D12: =IF(OR($C$5=0,C12=""),"",C12/$C$5) | F12: By nature (Table 2): materials, personnel/salaries, depreciation, other.
B13: − Depreciation & amortization (building 5,000 + website 6,000) | C13: -11000 | D13: =IF(OR($C$5=0,C13=""),"",C13/$C$5) -> -0.011652542 | F13: Homework cases often mix the two (like DSJ: salaries, rent, depreciation, other opex). That's why both kinds of line are here. Never put the same cost on two lines.
B14: − Bad debt expense (uncollectible receivables) | C14: -10000 | D14: =IF(OR($C$5=0,C14=""),"",C14/$C$5) -> -0.01059322 | F14: Classic mistakes
B15: +/− Loss on sale of old furniture & equipment (9,000 − 16,000) | C15: -7000 | D15: =IF(OR($C$5=0,C15=""),"",C15/$C$5) -> -0.0074152542 | F15: Revenue is recognised on DELIVERY, not when cash is received. Customer deposits are a liability, not revenue.
B16: = Operating profit (EBIT) | C16: =C7+C8+C9+C10+C11+C12+C13+C14+C15 -> 327000 | D16: =IF(OR($C$5=0,C16=""),"",C16/$C$5) -> 0.34639831 | F16: COGS is the cost of the units SOLD, not of the units purchased.
B17: + Financial income | D17: =IF(OR($C$5=0,C17=""),"",C17/$C$5) | F17: Only the part of prepaid rent used up in the period is an expense.
B18: − Financial expenses (interest) | D18: =IF(OR($C$5=0,C18=""),"",C18/$C$5) | F18: Interest expense accrues with time, whether or not it is paid.
B19: = Profit before tax | C19: =C16+C17+C18 -> 327000 | D19: =IF(OR($C$5=0,C19=""),"",C19/$C$5) -> 0.34639831 | F19: Loan principal repayments, dividends and asset purchases are NOT expenses.
B20: − Tax expense | D20: =IF(OR($C$5=0,C20=""),"",C20/$C$5) | F20: A gain or loss on selling PPE = price − book value. It goes in 'non-recurring items', not in sales.
B21: = Net profit from continuing operations | C21: =C19+C20 -> 327000 | D21: =IF(OR($C$5=0,C21=""),"",C21/$C$5) -> 0.34639831 | F21: Tax expense = tax rate × profit before tax (unless the case says otherwise).
B22: +/− Profit (loss) from discontinued operations | D22: =IF(OR($C$5=0,C22=""),"",C22/$C$5) | F22: Memo items
B23: = NET PROFIT | C23: =C21+C22 -> 327000 | D23: =IF(OR($C$5=0,C23=""),"",C23/$C$5) -> 0.34639831 | F23: D&A is filled in from the depreciation line. If depreciation is hidden inside COGS/SG&A, type the total over the formula.
B24: − Profit for minority (non-controlling) interests | D24: =IF(OR($C$5=0,C24=""),"",C24/$C$5) | F24: Gain/loss on sale: type it here as well so the indirect cash flow can remove it.
B25: = Net profit for parent company owners | C25: =C23+C24 -> 327000 | D25: =IF(OR($C$5=0,C25=""),"",C25/$C$5) -> 0.34639831 | F25: Check
F26: Compares net profit with the balance of the P&L T-account. Lines tagged # 'CE' (the closing entry) are ignored.
B27: Memo items (used by the indirect cash flow)
B28: Total D&A charged in 2011 incl. machinery 40,000 in product cost (positive) | C28: 51000
B29: Gain (+) / loss (−) on sale of non-current assets included above | C29: -7000
B31: Net profit according to the P&L T-account (excl. CE) | C31: =(SUM('T-Accounts'!$T$135:$T$150)-SUMIF('T-Accounts'!$U$135:$U$150,"CE",'T-Accounts'!$T$135:$T$150))-(SUM('T-Accounts'!$S$135:$S$150)-SUMIF('T-Accounts'!$R$135:$R$150,"CE",'T-Accounts'!$S$135:$S$150)) -> 327000
B32: CHECK: Income statement = P&L T-account | C32: =IF(ABS(C23-C31)<0.5,"OK","ERROR: "&TEXT(C23-C31,"#,##0")) -> OK

Sheet Cash Flow
B1: STATEMENT OF CASH FLOWS
B2: =Guide!$C$3&" – for the period "&Guide!$C$4&" (in "&Guide!$C$5&")" -> Maria Soldevila (company) – for the period 2011 (in €)
B4: A) DIRECT METHOD (list of cash movements; + collections / − payments) | F4: Notes & reminders
B5: Operating activities | F5: Sign convention (CN-233-E)
B6: + Collections from customers (incl. customer deposits) | C6: 850000 | F6: Cash collections are positive and cash payments negative. Type −20,000 for a payment.
B7: + Interest / dividends received | F7: Direct method: where the numbers come from
B8: − Payments to raw-material suppliers | C8: -250000 | F8: Go through the CASH T-account line by line. Every debit is a collection and every credit is a payment. Tag each one O, I or F.
B9: − Payments to employees (80,000 production + 100,000 S&A) | C9: -180000 | F9: Only CASH moves go here. Depreciation, purchases on credit, accruals and gains/losses never do.
B10: − Payments for rent (incl. prepaid rent) | F10: Classification
B11: − Other manufacturing (82,000) and S&A (50,000) expenses | C11: -132000 | F11: Operating: customers, suppliers, employees, rent, utilities, INTEREST paid and TAXES paid.
B12: − Payments for interest | F12: Investing: buying/selling land, buildings, equipment, software, shares of other companies.
B13: − Payments for taxes | F13: Financing: share issues, new loans, repaying loan/mortgage PRINCIPAL, dividends paid.
B14: = Cash flow from operating activities (CFO) | C14: =C6+C7+C8+C9+C10+C11+C12+C13 -> 288000 | F14: A mortgage/loan repayment is FINANCING (principal). Its interest is OPERATING.
F15: Paying a seller later for a building/land bought on credit is an investing outflow when paid.
B16: Investing activities | F16: Selling PPE: the whole cash received goes in CFI. The gain/loss is only an adjustment in the indirect CFO.
B17: − Purchase of machinery (80,000 in January + 160,000 in September) | C17: -240000 | F17: Marketable securities maturing in under 3 months are cash equivalents, so there is no cash flow line.
B18: − Purchase of new furniture & equipment | C18: -25000 | F18: Indirect method (automatic)
B19: − Purchase of intangible assets (software, patents) | F19: Starts from net profit and uses the Balance Sheet changes (Δ = EB − BB). Assets: minus the increase. Liabilities: plus the increase.
B20: − Investment in shares / marketable securities | F20: It only matches the direct method if the Income Statement memo items (D&A, gain/loss) are filled in.
B21: + Sale of old furniture & equipment | C21: 9000 | F21: Dividends payable, loans and mortgages are NOT operating liabilities, so they are left out on purpose.
B22: + Sale of shares / marketable securities | F22: Checks
B23: = Cash flow from (used in) investing activities (CFI) | C23: =C17+C18+C19+C20+C21+C22 -> -256000 | F23: 1) Ending cash = Balance Sheet cash. 2) Indirect CFO = direct CFO. 3) The three flows explain the change in cash.
F24: If check 2 fails, open the CF Worksheet sheet to find the account that isn't explained.
B25: Financing activities
B26: + Issue of share capital (incl. share premium)
B27: + New loans / mortgages received
B28: − Loan & mortgage repayments (principal only)
B29: − Dividends paid | C29: -30000
B30: = Cash flow from (used in) financing activities (CFF) | C30: =C26+C27+C28+C29 -> -30000
B32: CHANGE IN CASH (CFO + CFI + CFF) | C32: =C14+C23+C30 -> 2000
B33: Cash, beginning balance | C33: ='Balance Sheet'!C7 -> 101000
B34: Change in cash during the period | C34: =C32 -> 2000
B35: Cash, ending balance | C35: =C33+C32 -> 103000
B36: CHECK: ending cash = Balance Sheet cash | C36: =IF(ABS(C35-'Balance Sheet'!D7)<0.5,"OK","ERROR: "&TEXT(C35-'Balance Sheet'!D7,"#,##0")) -> OK
B37: Free cash flow (CFO + CFI, as in the course example) | C37: =C14+C23 -> 32000
B39: B) INDIRECT METHOD for CFO (net profit ± adjustments; automatic)
B40: Operating activities
B41: Net profit | C41: ='Income Statement'!C23 -> 327000
B42: + Depreciation & amortization | C42: ='Income Statement'!C28 -> 51000
B43: − Gains / + losses on sale of non-current assets | C43: =-'Income Statement'!C29 -> 7000
...

Sheet CF Worksheet
B1: CASH FLOW WORKSHEET ΔCash = −ΔAssets other than cash + ΔL + ΔOE
B2: =Guide!$C$3&" – "&Guide!$C$4 -> Maria Soldevila (company) – 2011
B4: Balance sheet account | C4: Change (sign-adjusted) | D4: CFO (net profit ± adj.) | E4: CFI (cash only) | F4: CFF (cash only) | G4: Unexplained (must be 0) | H4: Explanation (e.g. dep 54 + loss 7) | J4: Notes & reminders
B5: Assets other than cash (reverse the sign: an increase uses cash) | J5: What this is
B6: ="−Δ "&'T-Accounts'!$G$7 -> −Δ Marketable securities | C6: =-'Balance Sheet'!E8 -> 0 | G6: =C6-SUM(D6:F6) -> 0 | J6: The course's spreadsheet approach (CN-233-E, p. 4–8). Explain the change in every non-cash account and you have explained the change in cash.
B7: ="−Δ "&'T-Accounts'!$B$28 -> −Δ Accounts receivable | C7: =-'Balance Sheet'!E9 -> -84000 | D7: -84000 | G7: =C7-SUM(D7:F7) -> 0 | H7: 944,000 sales − 850,000 collected − 10,000 bad debts | J7: Optional, but it's the best way to find a mistake in the indirect method.
B8: ="−Δ "&'T-Accounts'!$G$28 -> −Δ Finished goods inventory | C8: =-'Balance Sheet'!E10 -> -5000 | D8: -5000 | G8: =C8-SUM(D8:F8) -> 0 | H8: Finished goods 32,000 → 37,000 (50 units × 740) | J8: How to fill
B9: ="−Δ "&'T-Accounts'!$B$49 -> −Δ Raw materials inventory | C9: =-'Balance Sheet'!E11 -> -28000 | D9: -28000 | G9: =C9-SUM(D9:F9) -> 0 | H9: Raw materials 270,000 bought − 242,000 used | J9: Column C is automatic. Split it into CFO / CFI / CFF so that 'Unexplained' becomes 0.
B10: ="−Δ "&'T-Accounts'!$G$49 -> −Δ Work in progress (WIP) | C10: =-'Balance Sheet'!E12 -> 0 | D10: 0 | G10: =C10-SUM(D10:F10) -> 0 | H10: No work in progress at year end | J10: CFI and CFF: only real cash flows (purchase of PPE, loan repaid, dividends paid…).
B11: ="−Δ "&'T-Accounts'!$B$70 -> −Δ Land | C11: =-'Balance Sheet'!E15 -> 0 | G11: =C11-SUM(D11:F11) -> 0 | J11: CFO: net profit and non-cash adjustments (depreciation, losses, changes in working capital).
B12: ="−Δ "&'T-Accounts'!$B$91 -> −Δ Buildings | C12: =-'Balance Sheet'!E16 -> 0 | G12: =C12-SUM(D12:F12) -> 0 | J12: Several items in one cell: type a formula, e.g. =54+7, and write the story in column H.
B13: ="−Δ "&'T-Accounts'!$B$112 -> −Δ Furniture & equipment | C13: =-'Balance Sheet'!E19 -> -5000 | D13: =7000+4000 -> 11000 | E13: =-25000+9000 -> -16000 | G13: =C13-SUM(D13:F13) -> 0 | H13: New F&E −25,000 and sale +9,000 (CFI); loss 7,000 + AD removed 4,000 (CFO) | J13: Course example (ABC Co.)
B14: ="−Δ "&'T-Accounts'!$B$133 -> −Δ Machinery | C14: =-'Balance Sheet'!E22 -> -240000 | E14: -240000 | G14: =C14-SUM(D14:F14) -> 0 | H14: Machinery purchase (80,000 + 160,000) | J14: PPE net −6 = +54 depreciation (CFO) +7 loss on sale (CFO) −72 purchase (CFI) +5 sale (CFI).
B15: ="−Δ "&'T-Accounts'!$G$70 -> −Δ Website (net of amortization) | C15: =-'Balance Sheet'!E25 -> 6000 | D15: 6000 | G15: =C15-SUM(D15:F15) -> 0 | H15: Website amortization added back | J15: Retained earnings +34 = +44 net profit (CFO) −10 dividends (CFF).
B16: Contra-assets (accumulated depreciation lowers assets, so it is added back) | J16: Interest payable −2 → CFO. Bank loan −31 → CFF. New shares +15 → CFF.
B17: ="+Δ "&'T-Accounts'!$G$91 -> +Δ Accum. depreciation – Buildings | C17: =-'Balance Sheet'!E17 -> 5000 | D17: 5000 | G17: =C17-SUM(D17:F17) -> 0 | H17: Building depreciation added back | J17: Tips
B18: ="+Δ "&'T-Accounts'!$G$112 -> +Δ Accum. depreciation – Furn. & equip. | C18: =-'Balance Sheet'!E20 -> -4000 | D18: -4000 | G18: =C18-SUM(D18:F18) -> 0 | H18: AD of the furniture sold, removed | J18: If you did not record the closing entry, net profit sits in the P&L row: put it in CFO there.
B19: ="+Δ "&'T-Accounts'!$G$133 -> +Δ Accum. depreciation – Machinery | C19: =-'Balance Sheet'!E23 -> 40000 | D19: 40000 | G19: =C19-SUM(D19:F19) -> 0 | H19: Machinery depreciation (inside product cost) added back | J19: If you use separate accumulated depreciation accounts, the depreciation goes on those rows (CFO) and the PPE-at-cost row only shows purchases and disposals.
B20: Liabilities
B21: ="+Δ "&'T-Accounts'!$M$7 -> +Δ Accounts payable | C21: ='Balance Sheet'!E41 -> 20000 | D21: 20000 | G21: =C21-SUM(D21:F21) -> 0 | H21: Raw materials bought 270,000 − paid 250,000
B22: ="+Δ "&'T-Accounts'!$R$7 -> +Δ Salaries payable | C22: ='Balance Sheet'!E42 -> 0 | G22: =C22-SUM(D22:F22) -> 0
B23: ="+Δ "&'T-Accounts'!$M$28 -> +Δ Interest payable | C23: ='Balance Sheet'!E43 -> 0 | G23: =C23-SUM(D23:F23) -> 0
B24: ="+Δ "&'T-Accounts'!$R$28 -> +Δ Taxes payable | C24: ='Balance Sheet'!E44 -> 0 | G24: =C24-SUM(D24:F24) -> 0
B25: ="+Δ "&'T-Accounts'!$M$49 -> +Δ Deposits from customers (unearned rev.) | C25: ='Balance Sheet'!E45 -> 0 | G25: =C25-SUM(D25:F25) -> 0
B26: ="+Δ "&'T-Accounts'!$R$49 -> +Δ Dividends payable | C26: ='Balance Sheet'!E46 -> 0 | G26: =C26-SUM(D26:F26) -> 0
B27: ="+Δ "&'T-Accounts'!$M$70 -> +Δ Short-term loans / current portion LTD | C27: ='Balance Sheet'!E47 -> 0 | G27: =C27-SUM(D27:F27) -> 0
B28: ="+Δ "&'T-Accounts'!$R$70 -> +Δ Payable for machinery | C28: ='Balance Sheet'!E48 -> 0 | G28: =C28-SUM(D28:F28) -> 0
B29: ="+Δ "&'T-Accounts'!$M$91 -> +Δ Long-term bank loan | C29: ='Balance Sheet'!E37 -> 0 | G29: =C29-SUM(D29:F29) -> 0
B30: ="+Δ "&'T-Accounts'!$R$91 -> +Δ Mortgage / obligations on land & bldgs | C30: ='Balance Sheet'!E38 -> 0 | G30: =C30-SUM(D30:F30) -> 0
B31: Owners' equity
B32: ="+Δ "&'T-Accounts'!$M$112 -> +Δ Share capital | C32: ='Balance Sheet'!E31 -> 0 | G32: =C32-SUM(D32:F32) -> 0
B33: ="+Δ "&'T-Accounts'!$R$112 -> +Δ Share premium | C33: ='Balance Sheet'!E32 -> 0 | G33: =C33-SUM(D33:F33) -> 0
B34: ="+Δ "&'T-Accounts'!$M$133 -> +Δ Retained profits | C34: ='Balance Sheet'!E33 -> 297000 | D34: 327000 | F34: -30000 | G34: =C34-SUM(D34:F34) -> 0 | H34: Net profit 327,000 (CFO) − dividends 30,000 (CFF)
B35: ="+Δ "&'T-Accounts'!$R$133 -> +Δ Profit & loss for the period (P&L) | C35: ='Balance Sheet'!E34 -> 0 | G35: =C35-SUM(D35:F35) -> 0
B36: TOTALS = ΔCash | CFO | CFI | CFF | C36: =SUM(C6:C35) -> 2000 | D36: =SUM(D6:D35) -> 288000 | E36: =SUM(E6:E35) -> -256000 | F36: =SUM(F6:F35) -> -30000 | G36: =SUM(G6:G35) -> 0
B38: CHECK: total change = ΔCash on the Balance Sheet | C38: =IF(ABS(C36-'Balance Sheet'!E7)<0.5,"OK","ERROR: "&TEXT(C36-'Balance Sheet'!E7,"#,##0")) -> OK
B39: CHECK: every change explained | C39: =IF(SUMPRODUCT(ABS(G6:G35))<0.5,"OK","ERROR: "&TEXT(SUMPRODUCT(ABS(G6:G35)),"#,##0")) -> OK
B40: CHECK: CFO / CFI / CFF = Cash Flow sheet | C40: =IF(ABS(ABS(D36-'Cash Flow'!C14)+ABS(E36-'Cash Flow'!C23)+ABS(F36-'Cash Flow'!C30))<0.5,"OK","ERROR: "&TEXT(ABS(D36-'Cash Flow'!C14)+ABS(E36-'Cash Flow'!C23)+ABS(F36-'Cash Flow'!C30),"#,##0")) -> OK

Sheet Lists
A1: ='T-Accounts'!$B$7 -> Cash & cash equivalents | B1: A+ | C1: O
A2: ='T-Accounts'!$G$7 -> Marketable securities | B2: A− | C2: I
A3: ='T-Accounts'!$B$28 -> Accounts receivable | B3: L+ | C3: F
A4: ='T-Accounts'!$G$28 -> Finished goods inventory | B4: L− | C4: Non-cash
A5: ='T-Accounts'!$B$49 -> Raw materials inventory | B5: OE+
A6: ='T-Accounts'!$G$49 -> Work in progress (WIP) | B6: OE−
A7: ='T-Accounts'!$B$70 -> Land | B7: Rev (OE+)
A8: ='T-Accounts'!$G$70 -> Website (net of amortization) | B8: Exp (OE−)
A9: ='T-Accounts'!$B$91 -> Buildings | B9: Contra-A+
A10: ='T-Accounts'!$G$91 -> Accum. depreciation – Buildings | B10: Contra-A−
A11: ='T-Accounts'!$B$112 -> Furniture & equipment
A12: ='T-Accounts'!$G$112 -> Accum. depreciation – Furn. & equip.
A13: ='T-Accounts'!$B$133 -> Machinery
A14: ='T-Accounts'!$G$133 -> Accum. depreciation – Machinery
A15: ='T-Accounts'!$M$7 -> Accounts payable
A16: ='T-Accounts'!$R$7 -> Salaries payable
A17: ='T-Accounts'!$M$28 -> Interest payable
A18: ='T-Accounts'!$R$28 -> Taxes payable
A19: ='T-Accounts'!$M$49 -> Deposits from customers (unearned rev.)
A20: ='T-Accounts'!$R$49 -> Dividends payable
A21: ='T-Accounts'!$M$70 -> Short-term loans / current portion LTD
A22: ='T-Accounts'!$R$70 -> Payable for machinery
A23: ='T-Accounts'!$M$91 -> Long-term bank loan
A24: ='T-Accounts'!$R$91 -> Mortgage / obligations on land & bldgs
A25: ='T-Accounts'!$M$112 -> Share capital
A26: ='T-Accounts'!$R$112 -> Share premium
A27: ='T-Accounts'!$M$133 -> Retained profits
A28: ='T-Accounts'!$R$133 -> Profit & loss for the period (P&L)
