Workbook

Sheet Inputs
A1: Viscofan (BME:VIS) – Inputs (€M unless stated)
A2: Blue = hard-coded input · Black = formula · Green = link to another sheet · Yellow = key assumption
A3: Market data (valuation date 1 Oct 2026)
A4: Share price (€) | B4: 53.7 | E4: Team: Capital IQ quote, 1 Oct 2026
A5: Diluted shares (M) | B5: 46.20225 | E5: Capital IQ consensus avg. diluted shares FY26E (4 of 4 analysts); range 45.3M–47.0M
A6: Market capitalisation | B6: =B4*B5 -> 2481.0608 | E6: Price × diluted shares
A7: Total debt (US$M, Capital IQ LTM) | B7: 429.3 | E7: S&P Capital IQ Financials, LTM 30 Jun 2026 (Prompt 2, §1.2) – incl. leases and other financial liabilities
A8: Cash & equivalents (US$M, Capital IQ) | B8: 66 | E8: S&P Capital IQ Financials, LTM 30 Jun 2026 (Prompt 2, §1.2)
A9: Cash & equivalents (€M, balance sheet) | B9: 57.728 | E9: Viscofan H1 2026 Financial Supplement, balance sheet 30 Jun 2026 (Prompt 2, §1.1)
A10: Implied USD per EUR used by Capital IQ | B10: =B8/B9 -> 1.1432927 | E10: Cash in US$ ÷ cash in € – converts CIQ debt back to € on the same basis
A11: Total debt (€M) | B11: =B7/B10 -> 375.4944 | E11: CIQ total debt converted at implied rate
A12: Net debt incl. leases (€M) | B12: =B11-B9 -> 317.7664 | E12: Used for EV → equity bridge (conservative vs company 'net bank debt')
A13: Memo: net bank debt, company definition (€M) | B13: 283.3 | E13: Viscofan 1H26 results presentation p.12 (Jun 2026); Dec 2025: €206.1M
A14: Enterprise value (€M) | B14: =B6+B12 -> 2798.8272 | E14: Market cap + net debt
A16: Reported earnings (€M)
A17: FY2025A revenue | B17: 1252 | E17: FY2025 earnings release 25 Feb 2026 (Prompt 2, §2.3)
A18: 1H2025 revenue | B18: 618.8 | E18: 1H26 results presentation p.3/p.14
A19: 1H2026 revenue | B19: 629.8 | E19: 1H26 results presentation p.3/p.14
A20: LTM Jun-26 revenue | B20: =B17-B18+B19 -> 1263 | E20: FY25 − 1H25 + 1H26
A21: FY2025A EBITDA | B21: 290 | E21: FY2025 earnings release (Prompt 2, §2.3)
A22: 1H2025 EBITDA | B22: 145.2 | E22: 1H26 results presentation p.14
A23: 1H2026 EBITDA | B23: 134.5 | E23: 1H26 results presentation p.14
A24: LTM Jun-26 EBITDA | B24: =B21-B22+B23 -> 279.3 | E24: FY25 − 1H25 + 1H26
A25: LTM EBITDA margin | B25: =B24/B20 -> 0.22114014 | E25: Formula
A26: EV / LTM EBITDA (x) | B26: =B14/B24 -> 10.020864 | E26: Cross-check: Capital IQ trailing TEV/EBITDA 9.94x (Prompt 1, §5.2)
A27: Net debt / LTM EBITDA (x) | B27: =B12/B24 -> 1.1377243 | E27: Formula
A28: Net bank debt / LTM EBITDA (x) | B28: =B13/B24 -> 1.0143215 | E28: Company definition; Dec-25: 206.1/290.0 = 0.71x
A30: Consensus – S&P Capital IQ Estimates (€)
B31: FY2026E | C31: FY2027E | D31: FY2028E
A32: EBITDA (€M) | B32: 300.54 | C32: 328.06 | D32: 355.91 | E32: Team: Capital IQ consensus in EUR (9 of 9 analysts)
A33: Dividend per share (€) | B33: 3.29 | C33: 3.39 | D33: 3.54 | E33: Team: Capital IQ consensus (7–8 of 9). ~94% payout in FY26E → likely includes extraordinary component
A34: # analysts (EBITDA) | B34: 9 | C34: 9 | D34: 9
A35: Consensus target price (€) | B35: 78.68 | E35: S&P Capital IQ Estimates; 10 analysts, 5 Buy / 2 Outperform / 3 Hold / 0 Sell (Prompt 1, §4.4)
A36: Upside to consensus target | B36: =B35/B4-1 -> 0.46517691
A38: Trade parameters (team assumptions)
A39: Investment horizon (years) | B39: 1.75 | E39: Team: 18–24 months → mid-point 21 months (exit ~mid-2028)
A40: Stop-loss (% below entry) | B40: 0.15 | E40: Team assumption – sits above bear-case value
A41: Stop-loss price (€) | B41: =B4*(1-B40) -> 45.645 | E41: Formula
A42: FX overlay: share of position hedged (sell USD fwd vs EUR) | B42: 0.3 | E42: Team: ≈ North America share of revenue (31%, 1H26 pres. p.5). Protects against USD weakness

Sheet Scenarios
A1: Bear / Base / Bull – exit valuation on FY2027E EBITDA (€)
A2: Exit EV/EBITDA applied to FY27E EBITDA; net debt held flat (FY27 FCF ≈ dividends). No control premium (one share).
B4: Bear | C4: Base | D4: Bull | E4: Driver / source
A5: Probability | B5: 0.15 | C5: 0.5 | D5: 0.35 | E5: Team assumption (tilted to bull: Hormuz normalisation + H2 price increases)
A6: FY2027E EBITDA (€M) | B6: 285 | C6: 315 | D6: 340 | E6: Bear ≈ LTM (€279M) + modest growth; Base 4% below consensus €328M; Bull above consensus incl. Health/Pet
A7: Exit EV / EBITDA (x) | B7: 8 | C7: 10 | D7: 11.5 | E7: Bear ≈ peer median ~7.5–8x (Prompt 2 §6.4); Base = today's 10.0x (no re-rating); Bull = quality premium
A8: Implied enterprise value (€M) | B8: =B6*B7 -> 2280 | C8: =C6*C7 -> 3150 | D8: =D6*D7 -> 3910
A9: Less: net debt (€M) | B9: =Inputs!$B$12 -> 317.7664 | C9: =Inputs!$B$12 -> 317.7664 | D9: =Inputs!$B$12 -> 317.7664
A10: Equity value (€M) | B10: =B8-B9 -> 1962.2336 | C10: =C8-C9 -> 2832.2336 | D10: =D8-D9 -> 3592.2336
A11: Diluted shares (M) | B11: =Inputs!$B$5 -> 46.20225 | C11: =Inputs!$B$5 -> 46.20225 | D11: =Inputs!$B$5 -> 46.20225
A12: Value per share (€) | B12: =B10/B11 -> 42.47052 | C12: =C10/C11 -> 61.300772 | D12: =D10/D11 -> 77.750187
A13: Upside / (downside) vs €53.70 | B13: =B12/Inputs!$B$4-1 -> -0.20911508 | C13: =C12/Inputs!$B$4-1 -> 0.14154138 | D13: =D12/Inputs!$B$4-1 -> 0.44786196
A14: EBITDA vs consensus FY27E | B14: =B6/Inputs!$C$32-1 -> -0.13125648 | C14: =C6/Inputs!$C$32-1 -> -0.039809791 | D14: =D6/Inputs!$C$32-1 -> 0.036395781
A16: Trade summary
A17: Probability-weighted target price (€) | B17: =SUMPRODUCT(B5:D5,B12:D12) -> 64.23353 | E17: Headline 18–24m target price
A18: Price upside to target | B18: =B17/Inputs!B4-1 -> 0.19615512
A19: Probability check (must be 100%) | B19: =SUM(B5:D5) -> 1
A20: Upside / downside ratio (bull vs bear) | B20: =(D12-Inputs!B4)/(Inputs!B4-B12) -> 2.141701 | E20: Upside to bull ÷ downside to bear
A21: Dividends received over horizon (€/sh) | B21: =Inputs!B33+Inputs!C33 -> 6.68 | E21: FY26E + FY27E consensus DPS (interim Dec + final Jun); may include extraordinary
A22: Expected total shareholder return | B22: =(B17+B21)/Inputs!B4-1 -> 0.3205499
A23: Annualised expected TSR | B23: =(1+B22)^(1/Inputs!B39)-1 -> 0.1722028
A24: Stop-loss price (€) | B24: =Inputs!B41 -> 45.645 | E24: Exit if breached without thesis-confirming news
A25: Cross-check: base case at consensus FY27E EBITDA (€) | B25: =(Inputs!C32*C7-Inputs!B12)/Inputs!B5 -> 64.127474 | E25: Base multiple × consensus EBITDA
A26: Cross-check: EV/EBITDA FY27E implied by consensus TP (x) | B26: =(Inputs!B35*Inputs!B5+Inputs!B12)/Inputs!C32 -> 12.049501 | E26: What the Street's €78.68 target is paying
A27: Cross-check: DCF value per share (€) | B27: =DCF!B49 -> 61.03962 | E27: Intrinsic anchor – see DCF tab
A29: Scenario narratives
A30: Middle East / energy | B30: Cost shock persists into 2027 | C30: Gradual normalisation; H2-26 price increases stick | D30: Hormuz deal; gas & plastics fall back
A31: EUR/USD | B31: USD weakens again (key risk) | C31: Broadly flat | D31: USD strength → FX tailwind
A32: Volumes | B32: Market 2% growth | C32: Market 2–4% + share gains (cellulose) | D32: Above-market (gut replacement, Zacapu)
A33: Health & Pet Treats | B33: Ignored | C33: Small contribution | D33: Re-rated as growth option

Sheet DCF
A1: DCF – unlevered free cash flow, € M (valuation date 1 Oct 2026)
A2: End-year discounting from valuation date; Q4-2026 cash flow excluded (conservative). FY25A actuals for reference.
A4: Assumptions | B4: FY2025A | C4: FY2026E | D4: FY2027E | E4: FY2028E | F4: FY2029E | G4: FY2030E | H4: FY2031E
A5: Revenue growth | C5: 0.03 | D5: 0.05 | E5: 0.05 | F5: 0.045 | G5: 0.04 | H5: 0.035 | I5: FY26: 1H +1.8% reported, H2 helped by price increases/less FX; FY27–28 market 2–4% vol + price/mix + Zacapu
A6: EBITDA margin | B6: =B12/B11 -> 0.23162939 | C6: 0.217 | D6: 0.2325 | E6: 0.2375 | F6: 0.24 | G6: 0.24 | H6: 0.24 | I6: FY26 ≈ guidance low end; FY27 recovers to like-for-like level (1H26 LFL 23.1%); history 21.5–25%
A7: D&A (% of revenue) | C7: 0.067 | D7: 0.067 | E7: 0.067 | F7: 0.067 | G7: 0.067 | H7: 0.067 | I7: 1H26: EBITDA 134.5 − EBIT 91.8 = 42.7 → ~6.7% of revenue
A8: Capex (€M) | C8: 100 | D8: 110 | E8: 110 | F8: 104 | G8: 108 | H8: 112 | I8: FY26 company guidance €100M (pres. p.11); FY27–28 Beat'30 step-up (Czech plant 2028); FY29+ ≈7% of revenue
A9: Change in NWC (% of incremental revenue) | B9: 0.2 | I9: Inventories + receivables ≈ 64% of LTM sales (Jun-26 BS) net of payables → 20% assumed
A10: Tax rate on EBIT | B10: 0.22 | I10: 1H26 effective rate 21.5% (19.5 / 90.5)
A11: Revenue | B11: =Inputs!B17 -> 1252 | C11: =B11*(1+C5) -> 1289.56 | D11: =C11*(1+D5) -> 1354.038 | E11: =D11*(1+E5) -> 1421.7399 | F11: =E11*(1+F5) -> 1485.7182 | G11: =F11*(1+G5) -> 1545.1469 | H11: =G11*(1+H5) -> 1599.2271
A12: EBITDA | B12: =Inputs!B21 -> 290 | C12: =C11*C6 -> 279.83452 | D12: =D11*D6 -> 314.81383 | E12: =E11*E6 -> 337.66323 | F12: =F11*F6 -> 356.57237 | G12: =G11*G6 -> 370.83526 | H12: =H11*H6 -> 383.8145
A13: D&A | C13: =C11*C7 -> 86.40052 | D13: =D11*D7 -> 90.720546 | E13: =E11*E7 -> 95.256573 | F13: =F11*F7 -> 99.543119 | G13: =G11*G7 -> 103.52484 | H13: =H11*H7 -> 107.14821
A14: EBIT | C14: =C12-C13 -> 193.434 | D14: =D12-D13 -> 224.09329 | E14: =E12-E13 -> 242.40665 | F14: =F12-F13 -> 257.02925 | G14: =G12-G13 -> 267.31042 | H14: =H12-H13 -> 276.66628
A15: Taxes on EBIT | C15: =C14*$B$10 -> 42.55548 | D15: =D14*$B$10 -> 49.300524 | E15: =E14*$B$10 -> 53.329464 | F15: =F14*$B$10 -> 56.546435 | G15: =G14*$B$10 -> 58.808292 | H15: =H14*$B$10 -> 60.866582
A16: NOPAT | C16: =C14-C15 -> 150.87852 | D16: =D14-D15 -> 174.79277 | E16: =E14-E15 -> 189.07719 | F16: =F14-F15 -> 200.48281 | G16: =G14-G15 -> 208.50213 | H16: =H14-H15 -> 215.7997
A17: + D&A | C17: =C13 -> 86.40052 | D17: =D13 -> 90.720546 | E17: =E13 -> 95.256573 | F17: =F13 -> 99.543119 | G17: =G13 -> 103.52484 | H17: =H13 -> 107.14821
A18: − Capex | C18: =C8 -> 100 | D18: =D8 -> 110 | E18: =E8 -> 110 | F18: =F8 -> 104 | G18: =G8 -> 108 | H18: =H8 -> 112
A19: − Increase in NWC | C19: =(C11-B11)*$B$9 -> 7.512 | D19: =(D11-C11)*$B$9 -> 12.8956 | E19: =(E11-D11)*$B$9 -> 13.54038 | F19: =(F11-E11)*$B$9 -> 12.795659 | G19: =(G11-F11)*$B$9 -> 11.885746 | H19: =(H11-G11)*$B$9 -> 10.816028
A20: Unlevered FCF | C20: =C16+C17-C18-C19 -> 129.76704 | D20: =D16+D17-D18-D19 -> 142.61771 | E20: =E16+E17-E18-E19 -> 160.79338 | F20: =F16+F17-F18-F19 -> 183.23027 | G20: =G16+G17-G18-G19 -> 192.14122 | H20: =H16+H17-H18-H19 -> 200.13189 | I20: FY26E shown for reference only – not discounted
A21: Discount period (years from 1 Oct 2026) | D21: 1.25 | E21: =D21+1 -> 2.25 | F21: =E21+1 -> 3.25 | G21: =F21+1 -> 4.25 | H21: =G21+1 -> 5.25 | I21: FY27 cash flow received end-2027 = 1.25 years after valuation date
A22: Discount factor | D22: =1/(1+$B$37)^D21 -> 0.91192864 | E22: =1/(1+$B$37)^E21 -> 0.84708998 | F22: =1/(1+$B$37)^F21 -> 0.78686138 | G22: =1/(1+$B$37)^G21 -> 0.73091507 | H22: =1/(1+$B$37)^H21 -> 0.67894657
A23: PV of FCF | D23: =D20*D22 -> 130.05718 | E23: =E20*E22 -> 136.20646 | F23: =F20*F22 -> 144.17683 | G23: =G20*G22 -> 140.43892 | H23: =H20*H22 -> 135.87886
A25: WACC
A26: Risk-free rate | B26: 0.0358 | I26: Spain 10Y bond yield 2026E (S&P Capital IQ, Prompt 2 §7.1)
A27: Levered beta | B27: 0.85 | I27: Team assumption – low-beta non-cyclical food industrial (verify CIQ beta)
A28: Equity risk premium | B28: 0.055 | I28: Team assumption – European ERP
A29: Cost of equity | B29: =B26+B27*B28 -> 0.08255 | I29: CAPM
A30: Pre-tax cost of debt | B30: 0.038 | I30: Euribor/SOFR-referenced bank debt (Prompt 2 §7.1)
A31: After-tax cost of debt | B31: =B30*(1-B10) -> 0.02964
A32: Market cap (€M) | B32: =Inputs!B6 -> 2481.0608
A33: Net debt (€M) | B33: =Inputs!B12 -> 317.7664
A34: Equity weight | B34: =B32/(B32+B33) -> 0.88646445 | I34: Market-value weights
A35: Debt weight | B35: =B33/(B32+B33) -> 0.11353555
A36: Terminal growth | B36: 0.02 | I36: Team: ≈ long-run inflation; below casing-market volume growth (2–4%)
A37: WACC | B37: =B34*B29+B35*B31 -> 0.076542834
A39: Valuation
A40: Sum of PV of FCF FY27–31 | B40: =SUM(D23:H23) -> 686.75824
A41: Terminal-year FCF × (1+g) | B41: =H20*(1+B36) -> 204.13452
A42: Terminal value (Gordon growth) | B42: =B41/(B37-B36) -> 3610.2634
A43: PV of terminal value | B43: =B42*H22 -> 2451.176
...

Sheet Sensitivity
A1: Sensitivities – value per share (€); green = above €53.70, red = below
A3: 1) DCF: WACC (rows) × terminal growth (columns)
A4: WACC \ g | B4: 0.01 | C4: 0.015 | D4: 0.02 | E4: 0.025 | F4: 0.03
A5: 0.065 | B5: =(SUMPRODUCT(DCF!$D$20:$H$20,1/(1+$A5)^DCF!$D$21:$H$21)+DCF!$H$20*(1+B$4)/($A5-B$4)/(1+$A5)^DCF!$H$21-Inputs!$B$12)/Inputs!$B$5 -> 65.673366 | C5: =(SUMPRODUCT(DCF!$D$20:$H$20,1/(1+$A5)^DCF!$D$21:$H$21)+DCF!$H$20*(1+C$4)/($A5-C$4)/(1+$A5)^DCF!$H$21-Inputs!$B$12)/Inputs!$B$5 -> 71.69972 | D5: =(SUMPRODUCT(DCF!$D$20:$H$20,1/(1+$A5)^DCF!$D$21:$H$21)+DCF!$H$20*(1+D$4)/($A5-D$4)/(1+$A5)^DCF!$H$21-Inputs!$B$12)/Inputs!$B$5 -> 79.065263 | E5: =(SUMPRODUCT(DCF!$D$20:$H$20,1/(1+$A5)^DCF!$D$21:$H$21)+DCF!$H$20*(1+E$4)/($A5-E$4)/(1+$A5)^DCF!$H$21-Inputs!$B$12)/Inputs!$B$5 -> 88.272193 | F5: =(SUMPRODUCT(DCF!$D$20:$H$20,1/(1+$A5)^DCF!$D$21:$H$21)+DCF!$H$20*(1+F$4)/($A5-F$4)/(1+$A5)^DCF!$H$21-Inputs!$B$12)/Inputs!$B$5 -> 100.10967
A6: 0.07 | B6: =(SUMPRODUCT(DCF!$D$20:$H$20,1/(1+$A6)^DCF!$D$21:$H$21)+DCF!$H$20*(1+B$4)/($A6-B$4)/(1+$A6)^DCF!$H$21-Inputs!$B$12)/Inputs!$B$5 -> 59.402755 | C6: =(SUMPRODUCT(DCF!$D$20:$H$20,1/(1+$A6)^DCF!$D$21:$H$21)+DCF!$H$20*(1+C$4)/($A6-C$4)/(1+$A6)^DCF!$H$21-Inputs!$B$12)/Inputs!$B$5 -> 64.325736 | D6: =(SUMPRODUCT(DCF!$D$20:$H$20,1/(1+$A6)^DCF!$D$21:$H$21)+DCF!$H$20*(1+D$4)/($A6-D$4)/(1+$A6)^DCF!$H$21-Inputs!$B$12)/Inputs!$B$5 -> 70.233314 | E6: =(SUMPRODUCT(DCF!$D$20:$H$20,1/(1+$A6)^DCF!$D$21:$H$21)+DCF!$H$20*(1+E$4)/($A6-E$4)/(1+$A6)^DCF!$H$21-Inputs!$B$12)/Inputs!$B$5 -> 77.453686 | F6: =(SUMPRODUCT(DCF!$D$20:$H$20,1/(1+$A6)^DCF!$D$21:$H$21)+DCF!$H$20*(1+F$4)/($A6-F$4)/(1+$A6)^DCF!$H$21-Inputs!$B$12)/Inputs!$B$5 -> 86.479152
A7: 0.075 | B7: =(SUMPRODUCT(DCF!$D$20:$H$20,1/(1+$A7)^DCF!$D$21:$H$21)+DCF!$H$20*(1+B$4)/($A7-B$4)/(1+$A7)^DCF!$H$21-Inputs!$B$12)/Inputs!$B$5 -> 54.099748 | C7: =(SUMPRODUCT(DCF!$D$20:$H$20,1/(1+$A7)^DCF!$D$21:$H$21)+DCF!$H$20*(1+C$4)/($A7-C$4)/(1+$A7)^DCF!$H$21-Inputs!$B$12)/Inputs!$B$5 -> 58.183625 | D7: =(SUMPRODUCT(DCF!$D$20:$H$20,1/(1+$A7)^DCF!$D$21:$H$21)+DCF!$H$20*(1+D$4)/($A7-D$4)/(1+$A7)^DCF!$H$21-Inputs!$B$12)/Inputs!$B$5 -> 63.010024 | E7: =(SUMPRODUCT(DCF!$D$20:$H$20,1/(1+$A7)^DCF!$D$21:$H$21)+DCF!$H$20*(1+E$4)/($A7-E$4)/(1+$A7)^DCF!$H$21-Inputs!$B$12)/Inputs!$B$5 -> 68.801703 | F7: =(SUMPRODUCT(DCF!$D$20:$H$20,1/(1+$A7)^DCF!$D$21:$H$21)+DCF!$H$20*(1+F$4)/($A7-F$4)/(1+$A7)^DCF!$H$21-Inputs!$B$12)/Inputs!$B$5 -> 75.880422
A8: 0.08 | B8: =(SUMPRODUCT(DCF!$D$20:$H$20,1/(1+$A8)^DCF!$D$21:$H$21)+DCF!$H$20*(1+B$4)/($A8-B$4)/(1+$A8)^DCF!$H$21-Inputs!$B$12)/Inputs!$B$5 -> 49.556943 | C8: =(SUMPRODUCT(DCF!$D$20:$H$20,1/(1+$A8)^DCF!$D$21:$H$21)+DCF!$H$20*(1+C$4)/($A8-C$4)/(1+$A8)^DCF!$H$21-Inputs!$B$12)/Inputs!$B$5 -> 52.98905 | D8: =(SUMPRODUCT(DCF!$D$20:$H$20,1/(1+$A8)^DCF!$D$21:$H$21)+DCF!$H$20*(1+D$4)/($A8-D$4)/(1+$A8)^DCF!$H$21-Inputs!$B$12)/Inputs!$B$5 -> 56.993175 | E8: =(SUMPRODUCT(DCF!$D$20:$H$20,1/(1+$A8)^DCF!$D$21:$H$21)+DCF!$H$20*(1+E$4)/($A8-E$4)/(1+$A8)^DCF!$H$21-Inputs!$B$12)/Inputs!$B$5 -> 61.725322 | F8: =(SUMPRODUCT(DCF!$D$20:$H$20,1/(1+$A8)^DCF!$D$21:$H$21)+DCF!$H$20*(1+F$4)/($A8-F$4)/(1+$A8)^DCF!$H$21-Inputs!$B$12)/Inputs!$B$5 -> 67.403899
A9: 0.085 | B9: =(SUMPRODUCT(DCF!$D$20:$H$20,1/(1+$A9)^DCF!$D$21:$H$21)+DCF!$H$20*(1+B$4)/($A9-B$4)/(1+$A9)^DCF!$H$21-Inputs!$B$12)/Inputs!$B$5 -> 45.622248 | C9: =(SUMPRODUCT(DCF!$D$20:$H$20,1/(1+$A9)^DCF!$D$21:$H$21)+DCF!$H$20*(1+C$4)/($A9-C$4)/(1+$A9)^DCF!$H$21-Inputs!$B$12)/Inputs!$B$5 -> 48.538919 | D9: =(SUMPRODUCT(DCF!$D$20:$H$20,1/(1+$A9)^DCF!$D$21:$H$21)+DCF!$H$20*(1+D$4)/($A9-D$4)/(1+$A9)^DCF!$H$21-Inputs!$B$12)/Inputs!$B$5 -> 51.904309 | E9: =(SUMPRODUCT(DCF!$D$20:$H$20,1/(1+$A9)^DCF!$D$21:$H$21)+DCF!$H$20*(1+E$4)/($A9-E$4)/(1+$A9)^DCF!$H$21-Inputs!$B$12)/Inputs!$B$5 -> 55.830597 | F9: =(SUMPRODUCT(DCF!$D$20:$H$20,1/(1+$A9)^DCF!$D$21:$H$21)+DCF!$H$20*(1+F$4)/($A9-F$4)/(1+$A9)^DCF!$H$21-Inputs!$B$12)/Inputs!$B$5 -> 60.470756
A10: 0.09 | B10: =(SUMPRODUCT(DCF!$D$20:$H$20,1/(1+$A10)^DCF!$D$21:$H$21)+DCF!$H$20*(1+B$4)/($A10-B$4)/(1+$A10)^DCF!$H$21-Inputs!$B$12)/Inputs!$B$5 -> 42.181594 | C10: =(SUMPRODUCT(DCF!$D$20:$H$20,1/(1+$A10)^DCF!$D$21:$H$21)+DCF!$H$20*(1+C$4)/($A10-C$4)/(1+$A10)^DCF!$H$21-Inputs!$B$12)/Inputs!$B$5 -> 44.684297 | D10: =(SUMPRODUCT(DCF!$D$20:$H$20,1/(1+$A10)^DCF!$D$21:$H$21)+DCF!$H$20*(1+D$4)/($A10-D$4)/(1+$A10)^DCF!$H$21-Inputs!$B$12)/Inputs!$B$5 -> 47.544529 | E10: =(SUMPRODUCT(DCF!$D$20:$H$20,1/(1+$A10)^DCF!$D$21:$H$21)+DCF!$H$20*(1+E$4)/($A10-E$4)/(1+$A10)^DCF!$H$21-Inputs!$B$12)/Inputs!$B$5 -> 50.844797 | F10: =(SUMPRODUCT(DCF!$D$20:$H$20,1/(1+$A10)^DCF!$D$21:$H$21)+DCF!$H$20*(1+F$4)/($A10-F$4)/(1+$A10)^DCF!$H$21-Inputs!$B$12)/Inputs!$B$5 -> 54.695109
A12: 2) Exit multiple: FY27E EBITDA €M (rows) × EV/EBITDA (columns)
A13: EBITDA \ x | B13: 8 | C13: 9 | D13: 10 | E13: 11 | F13: 12
A14: 280 | B14: =($A14*B$13-Inputs!$B$12)/Inputs!$B$5 -> 41.604762 | C14: =($A14*C$13-Inputs!$B$12)/Inputs!$B$5 -> 47.665073 | D14: =($A14*D$13-Inputs!$B$12)/Inputs!$B$5 -> 53.725384 | E14: =($A14*E$13-Inputs!$B$12)/Inputs!$B$5 -> 59.785694 | F14: =($A14*F$13-Inputs!$B$12)/Inputs!$B$5 -> 65.846005
A15: 290 | B15: =($A15*B$13-Inputs!$B$12)/Inputs!$B$5 -> 43.336279 | C15: =($A15*C$13-Inputs!$B$12)/Inputs!$B$5 -> 49.61303 | D15: =($A15*D$13-Inputs!$B$12)/Inputs!$B$5 -> 55.88978 | E15: =($A15*E$13-Inputs!$B$12)/Inputs!$B$5 -> 62.166531 | F15: =($A15*F$13-Inputs!$B$12)/Inputs!$B$5 -> 68.443281
A16: 300 | B16: =($A16*B$13-Inputs!$B$12)/Inputs!$B$5 -> 45.067796 | C16: =($A16*C$13-Inputs!$B$12)/Inputs!$B$5 -> 51.560987 | D16: =($A16*D$13-Inputs!$B$12)/Inputs!$B$5 -> 58.054177 | E16: =($A16*E$13-Inputs!$B$12)/Inputs!$B$5 -> 64.547367 | F16: =($A16*F$13-Inputs!$B$12)/Inputs!$B$5 -> 71.040558
A17: 315 | B17: =($A17*B$13-Inputs!$B$12)/Inputs!$B$5 -> 47.665073 | C17: =($A17*C$13-Inputs!$B$12)/Inputs!$B$5 -> 54.482922 | D17: =($A17*D$13-Inputs!$B$12)/Inputs!$B$5 -> 61.300772 | E17: =($A17*E$13-Inputs!$B$12)/Inputs!$B$5 -> 68.118622 | F17: =($A17*F$13-Inputs!$B$12)/Inputs!$B$5 -> 74.936472
A18: 328.06 | B18: =($A18*B$13-Inputs!$B$12)/Inputs!$B$5 -> 49.926434 | C18: =($A18*C$13-Inputs!$B$12)/Inputs!$B$5 -> 57.026954 | D18: =($A18*D$13-Inputs!$B$12)/Inputs!$B$5 -> 64.127474 | E18: =($A18*E$13-Inputs!$B$12)/Inputs!$B$5 -> 71.227994 | F18: =($A18*F$13-Inputs!$B$12)/Inputs!$B$5 -> 78.328514
A19: 340 | B19: =($A19*B$13-Inputs!$B$12)/Inputs!$B$5 -> 51.993866 | C19: =($A19*C$13-Inputs!$B$12)/Inputs!$B$5 -> 59.352815 | D19: =($A19*D$13-Inputs!$B$12)/Inputs!$B$5 -> 66.711764 | E19: =($A19*E$13-Inputs!$B$12)/Inputs!$B$5 -> 74.070713 | F19: =($A19*F$13-Inputs!$B$12)/Inputs!$B$5 -> 81.429662
A20: 355 | B20: =($A20*B$13-Inputs!$B$12)/Inputs!$B$5 -> 54.591142 | C20: =($A20*C$13-Inputs!$B$12)/Inputs!$B$5 -> 62.274751 | D20: =($A20*D$13-Inputs!$B$12)/Inputs!$B$5 -> 69.958359 | E20: =($A20*E$13-Inputs!$B$12)/Inputs!$B$5 -> 77.641968 | F20: =($A20*F$13-Inputs!$B$12)/Inputs!$B$5 -> 85.325576
A22: €328.06M = consensus FY27E; €315M = team base

Sheet 1H26 Data
A1: 1H26 results – key data (€M) · Source: Viscofan Results Presentation Jan–Jun 2026
A3: P&L | B3: 1H26 | C3: 1H25 | D3: % chg | E3: LFL % chg | F3: Source
A4: Revenue | B4: 629.8 | C4: 618.8 | D4: =B4/C4-1 -> 0.017776341 | E4: 0.048 | F4: p.14
A5: EBITDA | B5: 134.5 | C5: 145.2 | D5: =B5/C5-1 -> -0.07369146 | E5: 0.031 | F5: p.14
A6: Operating profit (EBIT) | B6: 91.8 | C6: 101.8 | D6: =B6/C6-1 -> -0.098231827 | F6: p.14
A7: Net finance result | B7: -1.3 | C7: -18.1 | D7: =B7/C7-1 -> -0.9281768 | F7: p.10
A8: Profit before tax | B8: 90.5 | C8: 83.7 | D8: =B8/C8-1 -> 0.081242533 | F8: p.14
A9: Taxes | B9: -19.5 | C9: -14 | D9: =B9/C9-1 -> 0.39285714 | F9: p.14
A10: Net profit | B10: 71.3 | C10: 69.8 | D10: =B10/C10-1 -> 0.021489971 | F10: p.14
A11: EBITDA margin | B11: =B5/B4 -> 0.21355986 | C11: =C5/C4 -> 0.23464771 | D11: =B11-C11 -> -0.021087845 | E11: 0.231 | F11: LFL margin 23.1% (p.9)
A13: Q2 (2Q26 vs 2Q25) | B13: 2Q26 | C13: 2Q25 | D13: % chg | E13: LFL % chg | F13: Source
A14: Revenue | B14: 325 | C14: 311.5 | D14: =B14/C14-1 -> 0.043338684 | E14: 0.049 | F14: p.15
A15: EBITDA | B15: 71.1 | C15: 76.3 | D15: =B15/C15-1 -> -0.068152031 | E15: -0.024 | F15: p.15
A16: Net profit | B16: 37.7 | C16: 38.4 | D16: =B16/C16-1 -> -0.018229167 | F16: p.15
A17: Consumption costs YoY: 1Q26 / 2Q26 | B17: -0.022 | C17: 0.168 | F17: p.8 – Middle East cost shock in Q2
A19: Bridges 1H25 → 1H26 | B19: Revenue | C19: EBITDA | F19: Source
A20: 1H25 | B20: 618.8 | C20: 145.2 | F20: p.4 (revenue), p.9 (EBITDA; LFL incl. energy)
A21: Like-for-like (ex energy for revenue) | B21: 34.2 | C21: 4.5
A22: Like-for-like energy | B22: -4.6 | C22: 0
A23: FX | B23: -20.5 | C23: -14.6
A24: Scope (Pet Mania) | B24: 1.9 | C24: -0.6
A25: 1H26 | B25: =SUM(B20:B24) -> 629.8 | C25: =SUM(C20:C24) -> 134.5
A26: FX hit as % of 1H25 base | B26: =B23/B20 -> -0.033128636 | C26: =C23/C20 -> -0.10055096 | F26: FX hits EBITDA ~3x harder than revenue: USD sales vs MXN/BRL/EUR costs
A28: Revenue split 1H26 | B28: €M | C28: % total | D28: Reported | E28: LFL | F28: Source
A29: EMEA | B29: 254.8 | C29: =B29/Inputs!$B$19 -> 0.40457288 | D29: -0.012 | E29: -0.002 | F29: p.5 (regions)
A30: North America | B30: 194.3 | C30: =B30/Inputs!$B$19 -> 0.30851064 | D30: -0.002 | E30: 0.058 | F30: p.5 (regions)
A31: South America | B31: 99.2 | C31: =B31/Inputs!$B$19 -> 0.15751032 | D31: 0.111 | E31: 0.147 | F31: p.5 (regions)
A32: Asia-Pacific | B32: 81.4 | C32: =B32/Inputs!$B$19 -> 0.12924738 | D32: 0.06 | E32: 0.073 | F32: p.5 (regions)
A33: Food, Packaging & Ingredients | B33: 591.7 | C33: =B33/Inputs!$B$19 -> 0.9395046 | D33: 0.018 | F33: p.6 (divisions)
A34: Health | B34: 3.8 | C34: =B34/Inputs!$B$19 -> 0.0060336615 | D34: 0.573 | F34: p.6 (divisions)
A35: Pet treats | B35: 8.3 | C35: =B35/Inputs!$B$19 -> 0.013178787 | D35: 0.878 | F35: p.6 (divisions)
A36: Energy (cogeneration) | B36: 26 | C36: =B36/Inputs!$B$19 -> 0.041282947 | D36: -0.154 | F36: p.6 (divisions)
A37: Health + Pet as % of revenue | C37: =C34+C35 -> 0.019212448
A39: Cash flow & balance sheet | B39: €M | F39: Source
A40: Net bank debt Dec-25 | B40: 206.1 | F40: p.12 – check vs reported €283.3M
A41: EBITDA | B41: -134.5
A42: Tax paid | B42: 21.9
A43: Working capital change | B43: 41.3
A44: Capex | B44: 34.5
A45: FX and others | B45: 7
...

Sheet Peers
A1: Comparables (secondary cross-check)
A3: Company | B3: TEV/EBITDA | C3: P/E trailing | D3: EBITDA margin | E3: Net margin | F3: Note / source
A4: Viscofan (BME:VIS) | B4: 9.94 | C4: 15.02 | D4: 0.2145 | E4: 0.1279 | F4: S&P Capital IQ, priced 30 Sep 2026 (Prompt 1)
A5: Ebro Foods (BME:EBRO) | B5: 7.48 | C5: 12.45 | D5: 0.1325 | E5: 0.075 | F5: S&P Capital IQ (Prompt 1) – Spanish food benchmark
A6: Shenguan Holdings (HK:0829) | F6: Listed collagen-casing peer – fill from Capital IQ
A7: Devro / SARIA take-private (2022) | F7: Precedent transaction (control premium – reference only)
A9: Viscofan premium vs Ebro (TEV/EBITDA) | B9: =B4/B5-1 -> 0.32887701
